Workbook

Sheet 요약
B1: ICMDA 숙소배정 — 요약 (Overview)
B2: 데이터 v7 기준 · 모든 값은 수식으로 자동 갱신
B4: ■ 핵심 지표
B5: 총 참가자 (행 수) | C5: =COUNTA(참가자!A2:A714)
B6: 총 인원 (가족 포함) | C6: =SUMPRODUCT(VALUE("0"&참가자!AG2:AG714))
B7: 방 필요 인원 (배정필요≠No) | C7: =SUMPRODUCT((참가자!O2:O714<>"No")*VALUE("0"&참가자!AG2:AG714))
B8: 총 객실 수 | C8: =COUNTA(객실!A2:A130)
B9: 총 수용 인원 (정원 합) | C9: =SUM(객실!H2:H130)
B10: 수용 여유 (정원 − 방필요인원) | C10: =C9-C7
B12: ■ 참가자 — 카테고리별
B13: 무료숙소신청 - 개인 | C13: =COUNTIF(참가자!C2:C714,"무료숙소신청 - 개인")
B14: 무료숙소신청 - 가족 | C14: =COUNTIF(참가자!C2:C714,"무료숙소신청 - 가족")
B15: └ 가족 인원 (가족 포함) | C15: =SUMPRODUCT((참가자!C2:C714="무료숙소신청 - 가족")*VALUE("0"&참가자!AG2:AG714))
B16: NOC 위원 | C16: =COUNTIF(참가자!C2:C714,"NOC 위원")
B17: AFF | C17: =COUNTIF(참가자!C2:C714,"AFF")
B18: 중국 | C18: =COUNTIF(참가자!C2:C714,"중국")
B19: 자원봉사팀 | C19: =COUNTIF(참가자!C2:C714,"자원봉사팀")
B20: 찬양팀 | C20: =COUNTIF(참가자!C2:C714,"찬양팀")
B21: 미디어팀 | C21: =COUNTIF(참가자!C2:C714,"미디어팀")
B23: ■ 참가자 — 팀별 (팀 컬럼)
B24: 자원봉사팀 (전체) | C24: =COUNTIF(참가자!AN2:AN714,"자원봉사팀")
B25: └ 방 필요 (배정필요=Yes) | C25: =COUNTIFS(참가자!AN2:AN714,"자원봉사팀",참가자!O2:O714,"Yes")
B26: 찬양팀 | C26: =COUNTIF(참가자!AN2:AN714,"찬양팀")
B27: 미디어팀 | C27: =COUNTIF(참가자!AN2:AN714,"미디어팀")
B29: ■ 참가자 — 성별
B30: 남 (M) | C30: =COUNTIF(참가자!G2:G714,"M")
B31: 여 (F) | C31: =COUNTIF(참가자!G2:G714,"F")
B32: 미상 (?) | C32: =COUNTIF(참가자!G2:G714,"~?")
B34: ■ 참가자 — 결제상태
B35: Paid | C35: =COUNTIF(참가자!N2:N714,"Paid")
B36: Bursary Holder | C36: =COUNTIF(참가자!N2:N714,"Bursary Holder")
B37: NA | C37: =COUNTIF(참가자!N2:N714,"NA")
B39: ■ 참가자 — 숙박일수
B40: 1박 | C40: =COUNTIF(참가자!AB2:AB714,"1박")
B41: 2박 | C41: =COUNTIF(참가자!AB2:AB714,"2박")
B42: 3박 | C42: =COUNTIF(참가자!AB2:AB714,"3박")
B43: 4박 | C43: =COUNTIF(참가자!AB2:AB714,"4박")
B44: 5박 | C44: =COUNTIF(참가자!AB2:AB714,"5박")
B45: 6박 | C45: =COUNTIF(참가자!AB2:AB714,"6박")
B46: 7박 | C46: =COUNTIF(참가자!AB2:AB714,"7박")
...

Sheet 참가자
A1: 참가자ID | B1: 그룹ID | C1: 카테고리 | D1: 구분 | E1: 이름 | F1: 한글이름 | G1: 성별 | H1: 생년월일 | I1: 국적 | J1: 이메일 | K1: 소속 | L1: 직책 | M1: WB등급 | N1: 결제상태 | O1: 배정필요 | P1: 도착일 | Q1: 출발일 | R1: 6월26일 | S1: 6월27일 | T1: 6월28일 | U1: 6월29일 | V1: 6월30일 | W1: 7월1일 | X1: 7월2일 | Y1: 7월3일 | Z1: 7월4일 | AA1: 7월5일 | AB1: 숙박일수 | AC1: 본인 | AD1: 배우자 | AE1: 자녀 | AF1: 기타 | AG1: 총인원 | AH1: 동반자요약 | AI1: 배정숙소 | AJ1: 중요사항 | AK1: 비고 | AL1: 출처 | AM1: 검토필요 | AN1: 팀
A2: P0001 | B2: G-fam-01 | C2: 무료숙소신청 - 가족 | D2: 1 | E2: NZAME YOLANDE | G2: F | H2: 1957-07-15 | I2: Gabon | J2: yolandenzame@gmail.com | K2: Gabon Medical Chrétien | L2: Membre | M2: Middle income | N2: Paid | O2: Yes | P2: 6월29일 | Q2: 7월4일 | U2: ✓ | V2: ✓ | W2: ✓ | X2: ✓ | Y2: ✓ | Z2: ✓ | AB2: 6박 | AC2: 1 | AD2: 0 | AE2: 1 | AF2: 0 | AG2: 2 | AH2: Rebecca [딸] | AL2: FINAL
A3: P0002 | B3: G-fam-02 | C3: 무료숙소신청 - 가족 | D3: 2 | E3: PAUL STEPHEN ATARO AYELLA | G3: M | H3: 1977-03-02 | I3: Uganda | J3: atarodrpapa@gmail.com | K3: ICMDA | L3: Regional Representative East Africa | M3: Low income | N3: Bursary Holder | O3: Yes | P3: 6월29일 | Q3: 7월4일 | U3: ✓ | V3: ✓ | W3: ✓ | X3: ✓ | Y3: ✓ | Z3: ✓ | AB3: 6박 | AC3: 1 | AD3: 0 | AE3: 2 | AF3: 0 | AG3: 3 | AH3: ATARO JANE KARINA, FEMALE. ATARO NEEMA ANGIOLETTA, FEMALE DAUGHTERS 딸 2명 | AL3: FINAL
A4: P0003 | B4: G-fam-03 | C4: 무료숙소신청 - 가족 | D4: 3 | E4: PETER SATHIYANATHAN MICHEAL JOHN | G4: M | H4: 1978-03-24 | I4: Malaysia | J4: doctorpeter@hotmail.com | K4: Healthcare Christian Fellowship Malaysia | L4: Doctor | M4: Middle income | N4: Paid | O4: Yes | P4: 7월1일 | Q4: 7월4일 | W4: ✓ | X4: ✓ | Y4: ✓ | Z4: ✓ | AB4: 4박 | AC4: 1 | AD4: 0 | AE4: 1 | AF4: 0 | AG4: 2 | AH4: IRINE AARATHANA PETER SATHIYANATHAN [딸, 12세] | AL4: FINAL
A5: P0004 | B5: G-fam-04 | C5: 무료숙소신청 - 가족 | D5: 4 | E5: SEMBY, JOHAN KYUNG HWA | G5: M | H5: 1966-01-20 | I5: Sweden | J5: johan.semby@gmail.com | K5: Linköping University/Linköping University Hospital Department Of Opthalmology/ ICMDA Sweden | L5: Senior Consultant In Ophthalmology/ Leader, Organizer For The Delegation From ICMDA Sweden And Finland | M5: High income | N5: Paid | O5: Yes | P5: 6월29일 | Q5: 7월4일 | U5: ✓ | V5: ✓ | W5: ✓ | X5: ✓ | Y5: ✓ | Z5: ✓ | AB5: 6박 | AC5: 1 | AD5: 0 | AE5: 1 | AF5: 0 | AG5: 2 | AH5: Joshua Semby [아들] | AL5: FINAL
A6: P0005 | B6: G-fam-05 | C6: 무료숙소신청 - 가족 | D6: 5 | E6: NURGUL MAMYROVA | G6: F | H6: 1980-03-17 | I6: Kyrgyz Republic | J6: nurgulicmda@gmail.com | K6: ICMDA | L6: Doctor | M6: Middle income | N6: Paid | O6: Yes | P6: 6월29일 | Q6: 7월4일 | U6: ✓ | V6: ✓ | W6: ✓ | X6: ✓ | Y6: ✓ | Z6: ✓ | AB6: 6박 | AC6: 1 | AD6: 1 | AE6: 2 | AF6: 0 | AG6: 4 | AH6: Simon Peter Nadeem [배우자(남편)] Shulmiyat Sarah Nadeem[딸, 18세] Timothy Simon Nadeem [아들, 13세] | AL6: FINAL
A7: P0006 | B7: G-fam-06 | C7: 무료숙소신청 - 가족 | D7: 6 | E7: DIANA | F7: Safina | G7: F | H7: 1982-10-29 | I7: Russian Federation | J7: diana.safina316@gmail.com | K7: ICMDA | L7: Regional Representative, Eurasia Training Administrator | M7: High income | N7: Bursary Holder | O7: Yes | P7: 6월29일 | Q7: 7월4일 | U7: ✓ | V7: ✓ | W7: ✓ | X7: ✓ | Y7: ✓ | Z7: ✓ | AB7: 6박 | AC7: 1 | AD7: 0 | AE7: 1 | AF7: 0 | AG7: 2 | AH7: Daria Safina [딸, 13세] | AL7: FINAL | AM7: 한글이름 확인
A8: P0007 | B8: G-fam-07 | C8: 무료숙소신청 - 가족 | D8: 7 | E8: PETER FEE | G8: M | H8: 1979-05-14 | I8: United Kingdom | J8: peterfee@doctors.org.uk | K8: Royal Belfast Children's Hospital, Belfast, UK | L8: Consultant Anaesthetist | M8: High income | N8: Paid | O8: Yes | P8: 6월29일 | Q8: 7월4일 | U8: ✓ | V8: ✓ | W8: ✓ | X8: ✓ | Y8: ✓ | Z8: ✓ | AB8: 6박 | AC8: 1 | AD8: 1 | AE8: 3 | AF8: 0 | AG8: 5 | AH8: Kerry Fee [배우자(아내)] thefees@me.com Grace Fee [딸, 12세] Joel Fee [아들, 14세] Toby Fee [아들, 10세] | AL8: FINAL
A9: P0008 | B9: G-fam-08 | C9: 무료숙소신청 - 가족 | D9: 8 | E9: GRETA GAMAL NAZIR KROSS | G9: F | H9: 1983-01-12 | I9: Egypt, Arab Rep. | J9: gretagamal@hotmail.com | K9: Cmf Egypt | L9: Pediatric Specialist (director Of Operations Of Cmf Egypt) | M9: Middle income | N9: Bursary Holder | O9: Yes | P9: 6월29일 | Q9: 7월4일 | U9: ✓ | V9: ✓ | W9: ✓ | X9: ✓ | Y9: ✓ | Z9: ✓ | AB9: 6박 | AC9: 1 | AD9: 1 | AE9: 2 | AF9: 0 | AG9: 4 | AH9: George robile [배우자(남편)] gretagamal@hotmail.com Jason george [아들, 13세] Jenny george [딸, 17세] | AL9: FINAL
A10: P0009 | B10: G-fam-09 | C10: 무료숙소신청 - 가족 | D10: 9 | E10: MASRA NGARMBAYE | G10: M | H10: 1985-01-18 | I10: Chad | J10: nmasra@yahoo.com | K10: Association Des Medecins Et Dentistes Chretiens Du Tchad- AMDCT | L10: Doctor Member | M10: Low income | N10: Bursary Holder | O10: Yes | P10: 6월29일 | Q10: 7월4일 | U10: ✓ | V10: ✓ | W10: ✓ | X10: ✓ | Y10: ✓ | Z10: ✓ | AB10: 6박 | AC10: 1 | AD10: 1 | AE10: 1 | AF10: 0 | AG10: 3 | AH10: Edith Dekoum Nelembaye [배우자(아내)] Manaseth Toulaboua Ngarmbaye [아들, 2세] | AL10: FINAL
A11: P0010 | B11: G-fam-10 | C11: 무료숙소신청 - 가족 | D11: 10 | E11: SOFAKO AMÉGANVI EGLOH | G11: M | H11: 1981-03-14 | I11: Togo | J11: esofak81@gmail.com | K11: CMF Togo | L11: Doctor | M11: Low income | N11: Bursary Holder | O11: Yes | P11: 6월29일 | Q11: 7월4일 | U11: ✓ | V11: ✓ | W11: ✓ | X11: ✓ | Y11: ✓ | Z11: ✓ | AB11: 6박 | AC11: 1 | AD11: 1 | AE11: 1 | AF11: 0 | AG11: 3 | AH11: Afi Kafui BANIBA ATOKO Epse EGLOH [배우자(아내)] Betsaleel Ewousika Améganvi EGLOH [자녀, 3세] | AL11: FINAL
A12: P0011 | B12: G-fam-11 | C12: 무료숙소신청 - 가족 | D12: 11 | E12: TRAY CHEAVKUN | G12: M | H12: 1989-08-13 | I12: Cambodia | J12: traykun@live.com | K12: Cambodian Christian Medical Fellowship | L12: Member | M12: Middle income | N12: Bursary Holder | O12: Yes | P12: 7월2일 | Q12: 7월4일 | X12: ✓ | Y12: ✓ | Z12: ✓ | AB12: 3박 | AC12: 1 | AD12: 1 | AE12: 1 | AF12: 0 | AG12: 3 | AH12: ANG SREYNIN [배우자(아내)] one daughter [딸, 3세] | AL12: FINAL
A13: P0012 | B13: G-fam-12 | C13: 무료숙소신청 - 가족 | D13: 12 | E13: GENA KEROLLOS DAWOOD GERGES | G13: F | H13: 1990-04-17 | I13: Egypt, Arab Rep. | J13: genakerollos@gmail.com | K13: CMF | L13: ENT Specialist | M13: Middle income | N13: Bursary Holder | O13: Yes | P13: 6월29일 | Q13: 7월4일 | U13: ✓ | V13: ✓ | W13: ✓ | X13: ✓ | Y13: ✓ | Z13: ✓ | AB13: 6박 | AC13: 1 | AD13: 1 | AE13: 2 | AF13: 0 | AG13: 4 | AH13: Ramy nabil [배우자(남편)] holy ramy [딸, 11세] heaven ramy [딸, 6세] | AL13: FINAL
A14: P0013 | B14: G-fam-13 | C14: 무료숙소신청 - 가족 | D14: 13 | E14: DONALD KAFA | G14: M | H14: 1976-11-04 | I14: Solomon Islands | J14: kafadonald@gmail.com | K14: Oceania ICMDA | L14: Medical Doctor | M14: Middle income | N14: Bursary Holder | O14: Yes | P14: 6월29일 | Q14: 7월1일 | U14: ✓ | V14: ✓ | W14: ✓ | AB14: 3박 | AC14: 1 | AD14: 0 | AE14: 1 | AF14: 0 | AG14: 2 | AH14: Elnisha Donald Kafa [아들, 13세] | AL14: FINAL
A15: P0014 | B15: G-fam-14 | C15: 무료숙소신청 - 가족 | D15: 14 | E15: PRISCILIA PRATAMI INTAN | G15: F | H15: 1992-07-09 | I15: Indonesia | J15: priscilia.pratami.intan@gmail.com | K15: CMDFI | L15: Saline Process Teamwork | M15: Middle income | N15: Bursary Holder | O15: Yes | P15: 6월29일 | Q15: 7월4일 | U15: ✓ | V15: ✓ | W15: ✓ | X15: ✓ | Y15: ✓ | Z15: ✓ | AB15: 6박 | AC15: 1 | AD15: 1 | AE15: 2 | AF15: 0 | AG15: 4 | AH15: Rudy.S [배우자(남편)] Kara Jessica Joetan [딸, 3세] Anya Kirana Joetan [딸] | AL15: FINAL
A16: P0015 | B16: G-fam-15 | C16: 무료숙소신청 - 가족 | D16: 15 | E16: PHOEM | F16: CHANTHEN | G16: F | H16: 1992-07-17 | I16: Cambodia | J16: drsam0701@gmail.com | K16: Cambodian Chrsitian Medical Fellowship | L16: Key Volunteer | M16: Middle income | N16: Bursary Holder | O16: Yes | P16: 7월1일 | Q16: 7월4일 | W16: ✓ | X16: ✓ | Y16: ✓ | Z16: ✓ | AB16: 4박 | AC16: 1 | AD16: 0 | AE16: 1 | AF16: 0 | AG16: 2 | AH16: Limeng Lichi [딸, 16세] | AL16: FINAL | AM16: 한글이름 확인
A17: P0016 | B17: G-fam-16 | C17: 무료숙소신청 - 가족 | D17: 16 | E17: RANI DWI CAHYANIPUTRI | G17: F | H17: 1986-08-20 | I17: Indonesia | J17: rk.tulung@gmail.com | K17: Simore Ministry | L17: Director | M17: Middle income | N17: Bursary Holder | O17: Yes | P17: 6월29일 | Q17: 7월4일 | U17: ✓ | V17: ✓ | W17: ✓ | X17: ✓ | Y17: ✓ | Z17: ✓ | AB17: 6박 | AC17: 1 | AD17: 1 | AE17: 1 | AF17: 0 | AG17: 3 | AH17: Augustine Elizabeth Pattipeilohy [모] Danzel Bezalel Tulung[아들, 0세] | AL17: FINAL
A18: P0017 | B18: G-fam-17 | C18: 무료숙소신청 - 가족 | D18: 17 | E18: PHON SOPHAI | G18: M | H18: 1985-12-16 | I18: Cambodia | J18: uhs.sophai@gmail.com | K18: CCMF | L18: Medical Doctor | M18: Middle income | N18: Bursary Holder | O18: Yes | P18: 7월1일 | Q18: 7월4일 | W18: ✓ | X18: ✓ | Y18: ✓ | Z18: ✓ | AB18: 4박 | AC18: 1 | AD18: 1 | AE18: 1 | AF18: 0 | AG18: 3 | AH18: Dy Dalen [배우자(아내)] Phay Rattanak [딸, 7세] | AL18: FINAL
A19: P0018 | B19: G-fam-18 | C19: 무료숙소신청 - 가족 | D19: 18 | E19: SYBRAND JOHANNES DE VAAL | G19: M | H19: 1980-02-20 | I19: South Africa | J19: sjdevaal@gmail.com | K19: CMF South Africa | L19: Dr | M19: Middle income | N19: Paid | O19: Yes | P19: 6월30일 | Q19: 7월4일 | V19: ✓ | W19: ✓ | X19: ✓ | Y19: ✓ | Z19: ✓ | AB19: 5박 | AC19: 1 | AD19: 1 | AE19: 5 | AF19: 0 | AG19: 7 | AH19: Celeste de Vaal [배우자(아내)] Nienke de Vaal [딸] Lira de Vaal [딸] Thandi de Vaal [딸] Ariana de Vaal [딸] | AL19: FINAL
A20: P0019 | B20: G-fam-19 | C20: 무료숙소신청 - 가족 | D20: 19 | E20: PHAM THI HUYEN | G20: F | H20: 1986-09-14 | I20: Vietnam | J20: huyentrangshaloms@gmail.com | K20: Hong Phuc General Hospital, Hai Phong, Vietnam | L20: Pharmacist | M20: Middle income | N20: Bursary Holder | O20: Yes | P20: 7월2일 | Q20: 7월4일 | X20: ✓ | Y20: ✓ | Z20: ✓ | AB20: 3박 | AC20: 1 | AD20: 0 | AE20: 1 | AF20: 0 | AG20: 2 | AH20: Nguyen Pham Viet An [아들] | AL20: FINAL
A21: P0020 | B21: G-fam-20 | C21: 무료숙소신청 - 가족 | D21: 20 | E21: HAMADO | F21: Sawadogo | G21: M | H21: 1989-12-31 | I21: Burkina Faso | J21: hamadodavidsawadogo@gmail.com | K21: ICMDA | L21: Family Physician /RR | M21: Low income | N21: Bursary Holder | O21: Yes | P21: 6월29일 | Q21: 7월4일 | U21: ✓ | V21: ✓ | W21: ✓ | X21: ✓ | Y21: ✓ | Z21: ✓ | AB21: 6박 | AC21: 1 | AD21: 0 | AE21: 1 | AF21: 0 | AG21: 2 | AH21: Sawadogo Deogracias W [딸, 5세] | AL21: FINAL | AM21: 한글이름 확인
A22: P0021 | B22: G-fam-21 | C22: 무료숙소신청 - 가족 | D22: 21 | E22: JODI ISAACS WILES | G22: F | H22: 1980-04-16 | I22: South Africa | J22: jodiandmichaelwiles@gmail.com | K22: UKZN/Queen Nandi Regional Hospital/CMF South Africa Executive Committee Member | L22: Dr | M22: Middle income | N22: Paid | O22: Yes | P22: 7월2일 | Q22: 7월4일 | X22: ✓ | Y22: ✓ | Z22: ✓ | AB22: 3박 | AC22: 1 | AD22: 0 | AE22: 2 | AF22: 0 | AG22: 3 | AH22: Amia Wiles (딸, 11세) Cayla Wiles (딸, 9세) | AL22: FINAL
A23: P0022 | B23: G-fam-22 | C23: 무료숙소신청 - 가족 | D23: 22 | E23: KYUNGMIN JANG | F23: 장경민 | G23: M | H23: 1985-11-30 | I23: Korea, Rep. | J23: jang@hishandsonafrica.org | K23: His Hands On Africa (Rwanda) | L23: Dental Mission Director And Dental Surgeon | M23: High income | N23: Paid | O23: Yes | P23: 7월1일 | Q23: 7월4일 | W23: ✓ | X23: ✓ | Y23: ✓ | Z23: ✓ | AB23: 4박 | AC23: 1 | AD23: 1 | AE23: 2 | AF23: 0 | AG23: 4 | AH23: 김민희 (배우자) 장세린 (딸, 7세) 장하린(딸, 2세) | AL23: FINAL
A24: P0023 | B24: G-fam-23 | C24: 무료숙소신청 - 가족 | D24: 23 | E24: CHI MA | G24: F | H24: 1986-07-04 | I24: China | J24: mamachi07@gmail.com edgarwu@msn.com | K24: Peniel Church Muzha | L24: Doctor | M24: Middle income | N24: Paid | O24: Yes | P24: 6월29일 | Q24: 7월4일 | U24: ✓ | V24: ✓ | W24: ✓ | X24: ✓ | Y24: ✓ | Z24: ✓ | AB24: 6박 | AC24: 1 | AD24: 1 | AE24: 2 | AF24: 0 | AG24: 4 | AH24: PIN-HSIEN WU(배우자,남편) EN-JIE WU(딸) EN-QI WU(아들) | AL24: FINAL
A25: P0024 | B25: G-fam-24 | C25: 무료숙소신청 - 가족 | D25: 24 | E25: HELENA GOMES | G25: F | H25: 1944-11-11 | I25: Brazil | J25: gomesmibr@gmail.com | K25: CMF Brazil | L25: Mother Accompanying Applicant (Mireille Gomes) | M25: Middle income | N25: Paid | O25: Yes | P25: 6월29일 | Q25: 7월4일 | U25: ✓ | V25: ✓ | W25: ✓ | X25: ✓ | Y25: ✓ | Z25: ✓ | AB25: 6박 | AC25: 1 | AD25: 0 | AE25: 1 | AF25: 0 | AG25: 2 | AH25: Mireille Gomes(딸) | AL25: FINAL
A26: P0025 | B26: G-fam-25 | C26: 무료숙소신청 - 가족 | D26: 25 | E26: MANOLITA JUNASA | G26: F | H26: 1960-01-01 | I26: Philippines | J26: mallette.p@gmail.com | K26: Kavod Center For Special Persons | L26: Founder, Executive Director | M26: Middle income | N26: Paid | O26: Yes | P26: 6월29일 | Q26: 7월4일 | U26: ✓ | V26: ✓ | W26: ✓ | X26: ✓ | Y26: ✓ | Z26: ✓ | AB26: 6박 | AC26: 1 | AD26: 0 | AE26: 1 | AF26: 0 | AG26: 2 | AH26: KYLE DAVID JUNASA(아들) | AL26: FINAL
A27: P0026 | B27: G-fam-26 | C27: 무료숙소신청 - 가족 | D27: 25 | E27: KYLE DAVID JUNASA | G27: M | H27: 1995-05-18 | I27: Philippines | J27: mallette.p@gmail.com | K27: Kavod Center For Special Persons | L27: Co-founder, Coach | M27: Middle income | N27: Paid | O27: Yes | P27: 6월29일 | Q27: 7월4일 | U27: ✓ | V27: ✓ | W27: ✓ | X27: ✓ | Y27: ✓ | Z27: ✓ | AB27: 6박 | AC27: 1 | AD27: 0 | AE27: 0 | AF27: 1 | AG27: 2 | AH27: MANOLITA JUNASA(엄마) | AL27: FINAL
A28: P0027 | C28: 무료숙소신청 - 개인 | D28: 1 | E28: ELISA MABEL GALEANO GAMARRA | G28: F | H28: 1997-07-03 | I28: Paraguay | J28: elisamedoficial@gmail.com | K28: In The Process Of Having An Association In Paraguay | L28: Doctor | M28: Middle income | N28: Bursary Holder | O28: Yes | P28: 6월29일 | Q28: 7월4일 | U28: ✓ | V28: ✓ | W28: ✓ | X28: ✓ | Y28: ✓ | Z28: ✓ | AB28: 6박 | AC28: 1 | AG28: 1 | AL28: FINAL
A29: P0028 | C29: 무료숙소신청 - 개인 | D29: 2 | E29: BLESSINGS DENDERE | G29: F | H29: 1999-10-25 | I29: Zimbabwe | J29: blessingszd@gmail.com | K29: Christian Medical Fellowship | L29: Doctor | M29: Middle income | N29: Bursary Holder | O29: Yes | P29: 6월29일 | Q29: 7월4일 | U29: ✓ | V29: ✓ | W29: ✓ | X29: ✓ | Y29: ✓ | Z29: ✓ | AB29: 6박 | AC29: 1 | AG29: 1 | AL29: FINAL
A30: P0029 | C30: 무료숙소신청 - 개인 | D30: 3 | E30: MUHUMUZA NDAMAGE STEPHEN | G30: M | H30: 1979-11-19 | I30: Rwanda | J30: stephen20130@gmail.com | K30: Rwanda Christian Medical And Dental Organization | L30: Head Of Rwanda Christian Medical And A Dental Organization | M30: Low income | N30: Bursary Holder | O30: Yes | P30: 7월4일 | Q30: 7월4일 | Z30: ✓ | AB30: 1박 | AC30: 1 | AG30: 1 | AL30: FINAL
A31: P0030 | C31: 무료숙소신청 - 개인 | D31: 4 | E31: KILACH CAROLE JESANG | G31: F | H31: 1988-03-27 | I31: Kenya | J31: carolejesang@gmail.com | K31: Christian Medical Fellowship- Kenya | L31: Dr/Miss/ Regional Leader | M31: Middle income | N31: Paid | O31: Yes | P31: 6월29일 | Q31: 7월4일 | U31: ✓ | V31: ✓ | W31: ✓ | X31: ✓ | Y31: ✓ | Z31: ✓ | AB31: 6박 | AC31: 1 | AG31: 1 | AL31: FINAL
A32: P0031 | C32: 무료숙소신청 - 개인 | D32: 5 | E32: ALINE GARCIA PEREIRA | G32: F | H32: 1989-12-05 | I32: Brazil | J32: alinegpereira1@gmail.com | K32: Uniasselvi (University)/ MDC -Medicos De Cristo | L32: I Am Student Of Health Management (graduation). But I Am Also PHD | M32: Middle income | N32: Paid | O32: Yes | P32: 6월29일 | Q32: 7월4일 | U32: ✓ | V32: ✓ | W32: ✓ | X32: ✓ | Y32: ✓ | Z32: ✓ | AB32: 6박 | AC32: 1 | AG32: 1 | AL32: FINAL
A33: P0032 | C33: 무료숙소신청 - 개인 | D33: 6 | E33: MUGABA PROSCOVIA MUJEERE | G33: F | H33: 1979-03-29 | I33: Uganda | J33: drprosiemm@gmail.com | K33: Uganda Christian Medical Fellowship (UCMF) | L33: Chairperson Of UCMF National Executive Committee | M33: Low income | N33: Bursary Holder | O33: Yes | P33: 6월30일 | Q33: 7월4일 | V33: ✓ | W33: ✓ | X33: ✓ | Y33: ✓ | Z33: ✓ | AB33: 5박 | AC33: 1 | AG33: 1 | AL33: FINAL
A34: P0033 | C34: 무료숙소신청 - 개인 | D34: 7 | E34: THEODORUS HEDWIN KADRIANTO | G34: M | H34: 1988-07-03 | I34: Indonesia | J34: theodorus.hedwin@icmda.net | K34: ICMDA | L34: AEO For East Asia, Southeast Asia, Oceania | M34: Middle income | N34: Paid | O34: Yes | P34: 6월29일 | Q34: 7월4일 | U34: ✓ | V34: ✓ | W34: ✓ | X34: ✓ | Y34: ✓ | Z34: ✓ | AB34: 6박 | AC34: 1 | AG34: 1 | AL34: FINAL
A35: P0034 | C35: 무료숙소신청 - 개인 | D35: 8 | E35: ALINA | G35: F | H35: 1999-06-23 | I35: Belarus | J35: kurdunap@gmail.com | K35: Belarussian CMF | L35: Ophtalmologist | M35: Middle income | N35: Bursary Holder | O35: Yes | P35: 6월29일 | Q35: 7월4일 | U35: ✓ | V35: ✓ | W35: ✓ | X35: ✓ | Y35: ✓ | Z35: ✓ | AB35: 6박 | AC35: 1 | AG35: 1 | AL35: FINAL
A36: P0035 | C36: 무료숙소신청 - 개인 | D36: 9 | E36: BENJAMIN DUBE | G36: M | H36: 1996-08-25 | I36: Zimbabwe | J36: benjiedube25@gmail.com | K36: National University Of Science And Technology, Zimbabwe | L36: Chairperson, NUST Christian Medical Fellowship (CMF) | M36: Middle income | N36: Bursary Holder | O36: Yes | P36: 6월29일 | Q36: 7월4일 | U36: ✓ | V36: ✓ | W36: ✓ | X36: ✓ | Y36: ✓ | Z36: ✓ | AB36: 6박 | AC36: 1 | AG36: 1 | AL36: FINAL
A37: P0036 | C37: 무료숙소신청 - 개인 | D37: 10 | E37: NAKANJAKO | F37: Sharon | G37: F | H37: 1993-02-06 | I37: Uganda | J37: sharonnakanjako2023@gmail.com | K37: Uganda Christian Medical Fellowship | L37: Clinical Psychologist | M37: #REF! | N37: Bursary Holder | O37: Yes | P37: 6월29일 | Q37: 7월4일 | U37: ✓ | V37: ✓ | W37: ✓ | X37: ✓ | Y37: ✓ | Z37: ✓ | AB37: 6박 | AC37: 1 | AG37: 1 | AL37: FINAL | AM37: 한글이름 확인
A38: P0037 | C38: 무료숙소신청 - 개인 | D38: 11 | E38: CHRISTA ADELINE | G38: F | H38: 1997-01-27 | I38: Indonesia | J38: christa.adeline@icmda.net | K38: ICMDA | L38: Regional Representative For Southeast Asia | M38: Middle income | N38: Paid | O38: Yes | P38: 6월30일 | Q38: 7월4일 | V38: ✓ | W38: ✓ | X38: ✓ | Y38: ✓ | Z38: ✓ | AB38: 5박 | AC38: 1 | AG38: 1 | AL38: FINAL
A39: P0038 | C39: 무료숙소신청 - 개인 | D39: 12 | E39: QUACY ASHEEKE GRANT | G39: M | H39: 1985-07-29 | I39: Guyana | J39: qgrant@lausanne.org | K39: Lausanne Movement Caribbean/ICMDA Guyana-Caribbean | L39: Regional Director (Lausanne Movement Caribbean) | M39: High income | N39: Bursary Holder | O39: Yes | P39: 6월29일 | Q39: 7월4일 | U39: ✓ | V39: ✓ | W39: ✓ | X39: ✓ | Y39: ✓ | Z39: ✓ | AB39: 6박 | AC39: 1 | AG39: 1 | AL39: FINAL
A40: P0039 | C40: 무료숙소신청 - 개인 | D40: 13 | E40: LOUIE BENJAMIN KWON BOU | G40: M | H40: 2005-05-03 | I40: New Zealand | J40: bklouie@outlook.com | K40: University Of Otago | L40: Medical Student | M40: High income | N40: Paid | O40: Yes | P40: 6월29일 | Q40: 7월3일 | U40: ✓ | V40: ✓ | W40: ✓ | X40: ✓ | Y40: ✓ | AB40: 5박 | AC40: 1 | AG40: 1 | AL40: FINAL
...

Sheet 객실
A1: 객실ID | B1: 숙소 | C1: 동 | D1: 층 | E1: 호실 | F1: 객실유형 | G1: 성별구분 | H1: 정원 | I1: 이용가능기간 | J1: 필수온돌 | K1: 비고
A2: R001 | B2: 부영청소년수련원 | C2: A | D2: 1st | E2: 124 | F2: Korean Traditional | G2: Male | H2: 6 | I2: 6/29~7/5 | J2: Y
A3: R002 | B3: 부영청소년수련원 | C3: A | D3: 1st | E3: 125 | F3: Korean Traditional | G3: Male | H3: 6 | I3: 6/29~7/5 | J3: Y
A4: R003 | B4: 부영청소년수련원 | C4: A | D4: 1st | E4: 126 | F4: Korean Traditional | G4: Male | H4: 6 | I4: 6/29~7/5 | J4: Y
A5: R004 | B5: 부영청소년수련원 | C5: A | D5: 1st | E5: 127 | F5: Korean Traditional | G5: Male | H5: 6 | I5: 6/29~7/5 | J5: Y
A6: R005 | B6: 부영청소년수련원 | C6: A | D6: 1st | E6: 128 | F6: Korean Traditional | G6: Male | H6: 6 | I6: 6/29~7/5
A7: R006 | B7: 부영청소년수련원 | C7: A | D7: 1st | E7: 129 | F7: Korean Traditional | G7: Male | H7: 6 | I7: 6/29~7/5
A8: R007 | B8: 부영청소년수련원 | C8: A | D8: 1st | E8: 130 | F8: Korean Traditional | G8: Male | H8: 6 | I8: 6/29~7/5
A9: R008 | B9: 부영청소년수련원 | C9: A | D9: 1st | E9: 131 | F9: Korean Traditional | G9: Male | H9: 6 | I9: 6/29~7/5
A10: R009 | B10: 부영청소년수련원 | C10: A | D10: 1st | E10: 132 | F10: Korean Traditional | G10: Male | H10: 6 | I10: 6/29~7/5
A11: R010 | B11: 부영청소년수련원 | C11: A | D11: 1st | E11: 133 | F11: Korean Traditional | G11: Male | H11: 6 | I11: 6/29~7/5 | J11: Y
A12: R011 | B12: 부영청소년수련원 | C12: A | D12: 1st | E12: 134 | F12: Korean Traditional | G12: Male | H12: 6 | I12: 6/29~7/5 | J12: Y
A13: R012 | B13: 부영청소년수련원 | C13: A | D13: 1st | E13: 135 | F13: Korean Traditional | G13: Male | H13: 6 | I13: 6/29~7/5
A14: R013 | B14: 부영청소년수련원 | C14: A | D14: 1st | E14: 136 | F14: Korean Traditional | G14: Male | H14: 6 | I14: 6/29~7/5
A15: R014 | B15: 부영청소년수련원 | C15: A | D15: 1st | E15: 137 | F15: Korean Traditional | G15: Male | H15: 6 | I15: 6/29~7/5
A16: R015 | B16: 부영청소년수련원 | C16: A | D16: 1st | E16: 138 | F16: Korean Room | G16: Male | H16: 6 | I16: 6/29~7/5
A17: R016 | B17: 부영청소년수련원 | C17: A | D17: 2nd | E17: 226 | F17: Korean Traditional | G17: Female | H17: 6 | I17: 6/29~7/5
A18: R017 | B18: 부영청소년수련원 | C18: A | D18: 2nd | E18: 227 | F18: Bed For 2 | G18: Staff | H18: 2 | I18: 6/29~7/5
A19: R018 | B19: 부영청소년수련원 | C19: A | D19: 2nd | E19: 228 | F19: Korean Traditional | G19: Female | H19: 6 | I19: 6/29~7/5
A20: R019 | B20: 부영청소년수련원 | C20: A | D20: 2nd | E20: 229 | F20: Korean Traditional | G20: Female | H20: 6 | I20: 6/29~7/5
A21: R020 | B21: 부영청소년수련원 | C21: A | D21: 2nd | E21: 230 | F21: Korean Traditional | G21: Female | H21: 6 | I21: 6/29~7/5
A22: R021 | B22: 부영청소년수련원 | C22: A | D22: 2nd | E22: 231 | F22: Korean Traditional | G22: Female | H22: 6 | I22: 6/29~7/5
A23: R022 | B23: 부영청소년수련원 | C23: A | D23: 2nd | E23: 232 | F23: Korean Traditional | G23: Female | H23: 6 | I23: 6/29~7/5
A24: R023 | B24: 부영청소년수련원 | C24: A | D24: 2nd | E24: 233 | F24: Korean Traditional | G24: Female | H24: 6 | I24: 6/29~7/5
... A80: R079 | B80: 부영청소년수련원 | C80: B | D80: 2nd | E80: 225 | F80: Bed For 2 | G80: Staff | H80: 2 | I80: 6/29~7/5
A81: R080 | B81: 유어스호텔 | F81: Deluxe Twin | H81: 2 | I81: 6/29~7/6
A82: R081 | B82: 유어스호텔 | F82: Deluxe Twin | H82: 2 | I82: 6/29~7/6
A83: R082 | B83: 유어스호텔 | F83: Deluxe Twin | H83: 2 | I83: 6/29~7/6
A84: R083 | B84: 유어스호텔 | F84: Deluxe Twin | H84: 2 | I84: 6/29~7/6
A85: R084 | B85: 유어스호텔 | F85: Deluxe Twin | H85: 2 | I85: 6/29~7/6
A86: R085 | B86: 유어스호텔 | F86: Deluxe Twin | H86: 2 | I86: 6/29~7/6
A87: R086 | B87: 유어스호텔 | F87: Deluxe Twin | H87: 2 | I87: 6/29~7/6
A88: R087 | B88: 유어스호텔 | F88: Deluxe Twin | H88: 2 | I88: 6/29~7/6
A89: R088 | B89: 유어스호텔 | F89: Deluxe Twin | H89: 2 | I89: 6/29~7/6
A90: R089 | B90: 유어스호텔 | F90: Deluxe Twin | H90: 2 | I90: 6/29~7/6
A91: R090 | B91: 유어스호텔 | F91: Deluxe Twin | H91: 2 | I91: 6/29~7/6
A92: R091 | B92: 유어스호텔 | F92: Deluxe Twin | H92: 2 | I92: 6/29~7/6
... A130: R129 | B130: 유어스호텔 | F130: YOUUS Suite | H130: 4 | I130: 6/29~7/6
