Workbook

Sheet World Bank Categories
B2: World Bank Categories
B3: Country Name | C3: Gross National Income(GNI)
B4: Afghanistan | C4: Low income
B5: Albania | C5: Middle income
B6: Algeria | C6: Middle income
B7: American Samoa | C7: High income
B8: Andorra | C8: High income
B9: Angola | C9: Middle income
B10: Antigua and Barbuda | C10: High income
B11: Argentina | C11: Middle income
B12: Armenia | C12: Middle income
B13: Aruba | C13: High income
B14: Australia | C14: High income
... B220: Zimbabwe | C220: Middle income

Sheet 26.05.29 기준 전체 숙소 신청자 명단
A2: =COUNTA(B5:B14999) -> 926 | C2: Godsends 등록자 수 | D2: =COUNTIF(Q5:Q1063,"등록") -> 864 | F2: Godsends 미등록자 수 | G2: =COUNTIF(Q5:Q2999,"미등록") -> 61 | I2: paid 완료 | J2: =COUNTA(R5:R14999) -> 577
A4: Timestamp | B4: 1. Name As it appears on your passport | C4: 2. Name (Korean): | D4: 3. Gender: | E4: 4. Date of Birth: (MM-DD-YYYY) | F4: 5. Nationality As it appears on your passport | G4: 6. Affiliation School/Institution/Organization Name | H4: 7. Title/Position | I4: 8. World Bank Category Found on your Registration Tab | J4: 9. Email Address Must be the same email used for registration | K4: 10. ICMDA Event You Plan to Attend | L4: 11. Free Accommodation Request Dates | M4: 12. Accompanying Family Member(s)(Name/Gender/Relationship): Are you bringing family member(s)? If yes, please indicate how many will accompany you and provide their name, gender, and relationship (ex: 1, John Doe, male, husband, John_D@gmail.com) | N4: 동반자 전체 요악 | O4: 본인 포함 총 인원(가족 단위 경우만) | P4: 13. Consent for Personal Information Use I hereby consent to the collection and use of the personal information provided above for the purpose of evaluating my application for ICMDA free accommodation and for related communications. | Q4: 등록판정 | R4: Paid | S4: 매칭된 godsends 이름 | T4: 매칭된 godsends 생년월일 | U4: 매칭된 godsends 이메일 | V4: 판정 근거 | W4: Column 1
A5: 45841.453 | B5: Elisa Mabel Galeano Gamarra | D5: Female | E5: 35614 | F5: Paraguay | G5: in the process of having an association in Paraguay | H5: doctor | I5: =VLOOKUP(CLEAN(F5),'World Bank Categories'!$B$4:$C$220,2,FALSE) -> Middle income | J5: elisamedoficial@gmail.com | K5: Pre-Conference + Main Congress | L5: June 29, June 30, July 1, July 2, July 3, July 4 | P5: Agree | Q5: 등록 | R5: bursary | S5: Elisa Mabel Galeano Gamarra
A6: 45843.795 | B6: NZAME Yolande | D6: Female | E6: 21016 | F6: Gabon | G6: Gabon Medical Chrétien | H6: Membre | I6: =VLOOKUP(CLEAN(F6),'World Bank Categories'!$B$4:$C$220,2,FALSE) -> Middle income | J6: yolandenzame@gmail.com | K6: Main Congress Only | L6: June 29, June 30, July 1, July 2, July 3, July 4 | M6: Rebecca, féminin, fille, vierin.rebecca@hotmail.fr | N6: Rebecca [딸] | O6: 2명/ (자녀 1명) | P6: Agree | Q6: 등록 | R6: paid | S6: NZAME Yolande
A7: 45846.76 | B7: KALIBBALA EMMANUEL | D7: Male | E7: 36912 | F7: UGANDA | G7: Gulu University | H7: Mr. | I7: =VLOOKUP(CLEAN(F7),'World Bank Categories'!$B$4:$C$220,2,FALSE) -> Low income | J7: kalex122001@gmail.com | K7: Main Congress Only | L7: June 29, June 30, July 1, July 2, July 3, July 4 | P7: Agree | Q7: 등록 | S7: KALIBBALA EMMANUEL
A8: 45849.777 | B8: Edwin Njore Irungu | D8: Male | E8: 32541 | F8: Kenya | G8: PCEA Kikuyu Hospital | H8: Mr | I8: =VLOOKUP(CLEAN(F8),'World Bank Categories'!$B$4:$C$220,2,FALSE) -> Middle income | J8: irunguedwin8@gmail.com | K8: Main Congress Only | L8: June 29, June 30, July 1, July 2, July 3, July 4 | P8: Agree | Q8: 미등록
A9: 45853.25 | B9: Blessings Dendere | D9: Female | E9: 36458 | F9: Zimbabwe | G9: Christian Medical Fellowship | H9: Doctor | I9: =VLOOKUP(CLEAN(F9),'World Bank Categories'!$B$4:$C$220,2,FALSE) -> Middle income | J9: blessingszd@gmail.com | K9: Pre-Conference + Main Congress | L9: June 29, June 30, July 1, July 2, July 3, July 4 | P9: Agree | Q9: 등록 | R9: bursary | S9: Blessings Dendere
A10: 45856.25 | B10: Ilivieda Omamezi Annah | D10: Female | E10: 38134 | F10: Nigeria | G10: University of Ilorin | H10: Student | I10: =VLOOKUP(CLEAN(F10),'World Bank Categories'!$B$4:$C$220,2,FALSE) -> Middle income | J10: omasax94@gmail.com | K10: Student Conference + Main Congress | L10: June 29, June 30, July 1, July 2, July 3, July 4 | P10: Agree | Q10: 미등록
A11: 45856.751 | B11: AGNESS SAIMON KASWAGA | D11: Female | E11: 37063 | F11: Tanzania | G11: KCMC | H11: MEDICAL DOCTOR | I11: =VLOOKUP(CLEAN(F11),'World Bank Categories'!$B$4:$C$220,2,FALSE) -> Middle income | J11: Saimonagness58@gmail.com | K11: Main Congress Only | L11: June 29, June 30, July 1, July 2, July 3, July 4 | P11: Agree | Q11: 등록 | S11: AGNESS S KASWAGA | T11: 36698 | U11: Saimonagness58@gmail.com | V11: 이메일 일치, 이름 유사도 93
A12: 45857.619 | B12: Virginia Baraza Dangi | D12: Female | E12: 38314 | F12: Tanzania | G12: KCMC University | H12: Student | I12: =VLOOKUP(CLEAN(F12),'World Bank Categories'!$B$4:$C$220,2,FALSE) -> Middle income | J12: vibaseche23@gmail.com | K12: Pre-Conference + Main Congress | L12: June 29, June 30, July 1, July 2, July 3, July 4 | P12: Agree | Q12: 등록 | S12: Virginia Baraza Dangi | T12: 38314 | U12: Vibaseche23@gmail.com | V12: 생년월일 일치, 이메일 일치, 이름 완전일치
A13: 45859.287 | B13: Muhumuza Ndamage Stephen | C13: Not Korean | D13: Male | E13: 29178 | F13: Rwanda | G13: Rwanda Christian Medical and Dental Organization | H13: Head of Rwanda Christian Medical and a Dental Organization | I13: =VLOOKUP(CLEAN(F13),'World Bank Categories'!$B$4:$C$220,2,FALSE) -> Low income | J13: stephen20130@gmail.com | K13: Student Conference + Main Congress | L13: 46207 | P13: Agree | Q13: 등록 | R13: bursary | S13: Muhumuza Ndamage Stephen | T13: 29178 | U13: stephen20130@gmail.com | V13: 생년월일 일치, 이메일 일치, 이름 완전일치
A14: 45859.316 | B14: Modestin Nahimana | D14: Male | E14: 36278 | F14: Burundi | G14: Christian Medical Student Fellowship in Rwanda | H14: Member | I14: =VLOOKUP(CLEAN(F14),'World Bank Categories'!$B$4:$C$220,2,FALSE) -> Low income | J14: modestin.nahimana@gmail.com | K14: Student Conference + Main Congress | L14: June 29, June 30, July 1, July 2, July 3, July 4 | P14: Agree | Q14: 미등록
A15: 45859.598 | B15: UWIMANA Kevine | D15: Female | E15: 37368 | F15: Rwanda | G15: Rwanda Christian medical and dental organization | H15: Student | I15: =VLOOKUP(CLEAN(F15),'World Bank Categories'!$B$4:$C$220,2,FALSE) -> Low income | J15: kevineuwimana01@gmail.com | K15: Student Conference + Main Congress | L15: 46207 | Q15: 등록 | S15: Uwimana Kevine | T15: 37368 | U15: kevineuwimana01@gmail.com | V15: 생년월일 일치, 이메일 일치, 이름 완전일치
A16: 45859.6 | B16: Munezero Noella | D16: Female | E16: 35424 | F16: Rwanda | G16: Rwanda christian medical and dental organization | H16: Medical Doctor | I16: =VLOOKUP(CLEAN(F16),'World Bank Categories'!$B$4:$C$220,2,FALSE) -> Low income | J16: Munono 25@gmail.com | K16: Pre-Conference + Main Congress | L16: June 29, June 30, July 1, July 2, July 3, July 4 | P16: Agree | Q16: 등록 | S16: Munezero Noella | T16: 35424 | U16: Munono25@gmail.com | V16: 생년월일 일치, 이름 완전일치
A17: 45859.616 | B17: Uwizeyimana Marie Grace | D17: Female | E17: 37239 | F17: Rwanda | G17: Rwanda Christian medical and dental organization | H17: Student | I17: =VLOOKUP(CLEAN(F17),'World Bank Categories'!$B$4:$C$220,2,FALSE) -> Low income | J17: Umg | K17: Pre-Conference + Main Congress | L17: June 29, June 30, July 1, July 2, July 3, July 4 | P17: Agree | Q17: 미등록
A18: 45859.617 | B18: NIYOKWIZERWA Moise | D18: Male | E18: 37362 | F18: Rwanda | G18: Rwanda christian medical and dental organisation | H18: Student leader | I18: =VLOOKUP(CLEAN(F18),'World Bank Categories'!$B$4:$C$220,2,FALSE) -> Low income | J18: niyokwizerwamoise910@gmail.com | K18: Pre-Conference + Main Congress | L18: 46207 | P18: Agree | Q18: 등록 | S18: Niyokwizerwa Moise | T18: 37362 | U18: niyokwizerwamoise910@gmail.com | V18: 생년월일 일치, 이메일 일치, 이름 완전일치
A19: 45859.624 | B19: NIYIREMA Olive | D19: Female | E19: 35154 | F19: Rwanda | G19: Affiliation is RWanda Christian Medical and Dental Organization Not CMSF RWanda Christian Medical and Dental Organization | H19: Doctor | I19: =VLOOKUP(CLEAN(F19),'World Bank Categories'!$B$4:$C$220,2,FALSE) -> Low income | J19: olivenini2020@gmail.com | K19: Pre-Conference + Main Congress | L19: June 29, June 30, July 1, July 2, July 3, July 4 | P19: Agree | Q19: 등록 | S19: Olive NIYIREMA | T19: 35632 | U19: olivenini2020@gmail.com | V19: 이메일 일치, 이름 유사도 100, 이름 토큰 포함
A20: 45859.629 | B20: Tusahirwa innocent | D20: Male | E20: 37457 | F20: Rwanda | G20: Rwanda chritian medical and dental organisation | H20: Student's leader | I20: =VLOOKUP(CLEAN(F20),'World Bank Categories'!$B$4:$C$220,2,FALSE) -> Low income | J20: tuzahirwainnocent@gmail.com | K20: Student Conference + Main Congress | L20: June 29, June 30, July 1, July 2, July 3, July 4 | P20: Agree | Q20: 미등록
A21: 45859.641 | B21: ISHIMWE Jacques | C21: ISHIMWE Jacques | D21: Male | E21: 37622 | F21: Rwanda | G21: Rwanda Christian Medical and Dental organization | H21: Student | I21: =VLOOKUP(CLEAN(F21),'World Bank Categories'!$B$4:$C$220,2,FALSE) -> Low income | J21: asinathamukakarera@gmail.com | K21: Pre-Conference + Main Congress | L21: 46207 | P21: Agree | Q21: 등록 | S21: ISHIMWE Jacques | T21: 37622 | U21: asinathamukakarera@gmail.com | V21: 생년월일 일치, 이메일 일치, 이름 완전일치
A22: 45859.642 | B22: Uwingabire Marie Solange | D22: Female | E22: 38330 | F22: Rwanda | G22: University of Rwanda | H22: Student | I22: =VLOOKUP(CLEAN(F22),'World Bank Categories'!$B$4:$C$220,2,FALSE) -> Low income | J22: uwingabiresolange19@gmail.com | K22: Student Conference + Main Congress | L22: June 29, June 30, July 1, July 2, July 3, July 4 | P22: Agree | Q22: 미등록
A23: 45859.646 | B23: Tobi Joyce Omonefe | D23: Female | E23: 37760 | F23: Nigeria | G23: Rwanda Christian Medical and Dental Organization | H23: Student | I23: =VLOOKUP(CLEAN(F23),'World Bank Categories'!$B$4:$C$220,2,FALSE) -> Middle income | J23: joycie1619@gmail.com | K23: Pre-Conference + Main Congress | L23: 46207 | P23: Agree | Q23: 등록 | S23: Joyce Tobi | T23: 37760 | U23: joycie2124@gmail.com | V23: 생년월일 일치, 이름 유사도 100, 이름 토큰 포함
A24: 45859.655 | B24: Patrick GISUBIZO | D24: Male | E24: 37756 | F24: Rwanda | G24: University of Rwanda | H24: Mr. | I24: =VLOOKUP(CLEAN(F24),'World Bank Categories'!$B$4:$C$220,2,FALSE) -> Low income | J24: gisubizopatrick095@gmail.com | K24: Student Conference + Main Congress | L24: June 29, June 30, July 1, July 2, July 3, July 4 | P24: Agree | Q24: 미등록
A25: 45859.657 | B25: ABAYISENGA Stella | D25: Female | E25: 38183 | F25: Rwanda | G25: University of Rwanda | H25: Student | I25: =VLOOKUP(CLEAN(F25),'World Bank Categories'!$B$4:$C$220,2,FALSE) -> Low income | J25: stellabayisenga@gmail.com | K25: Student Conference + Main Congress | L25: June 29, June 30, July 1, July 2, July 3, July 4 | M25: 9, Stella,female, children, stellabayisenga@gmail.com | N25: Stella [자녀] | O25: 2명/ (자녀 1명) | P25: Agree | Q25: 미등록
A26: 45859.675 | B26: NGABOYUMWAMI Jean Paul | C26: Rwandan ID | D26: Male | E26: 37594 | F26: Rwanda | G26: University of Rwanda | H26: Medical Student | I26: =VLOOKUP(CLEAN(F26),'World Bank Categories'!$B$4:$C$220,2,FALSE) -> Low income | J26: jeanpaulngaboyumwami@gmail.com | K26: Student Conference + Main Congress | L26: June 29, June 30, July 1, July 2, July 3, July 4 | P26: Agree | Q26: 등록 | S26: NGABOYUMWAMI Jean Paul | T26: 45762 | U26: jeanpaulngaboyumwami@gmail.com | V26: 이메일 일치
A27: 45859.792 | B27: Mbonimpa James | D27: Male | E27: 37455 | F27: Rwanda | G27: RCMDO ( Rwanda Christian Medical and Dental Organisation | H27: Medical Student | I27: =VLOOKUP(CLEAN(F27),'World Bank Categories'!$B$4:$C$220,2,FALSE) -> Low income | J27: jamesmbonimpa904@gmail.com | K27: Pre-Conference + Main Congress | L27: June 29, June 30, July 1, July 2, July 3, July 4 | P27: Agree | Q27: 미등록
A28: 45860.185 | B28: Nsanzimfura Pacifique | C28: Nsanzimfura Pacifique | D28: Male | E28: 38109 | F28: Rwanda | G28: University of Rwanda | H28: Mr | I28: =VLOOKUP(CLEAN(F28),'World Bank Categories'!$B$4:$C$220,2,FALSE) -> Low income | J28: nsanzimfurapacifique@gmail.com | K28: Student Conference + Main Congress | L28: June 29, June 30, July 1, July 2, July 3, July 4 | P28: Agree | Q28: 등록 | S28: Nsanzimfura Pacifique | T28: 38109 | U28: nsanzimfurapacifique@gmail.com | V28: 생년월일 일치, 이메일 일치, 이름 완전일치
A29: 45860.593 | B29: Jean d'Amour HABINSHUTI | D29: Male | E29: 34335 | F29: Rwanda | G29: Rwanda Christian Medical and Dental Organization | H29: Student | I29: =VLOOKUP(CLEAN(F29),'World Bank Categories'!$B$4:$C$220,2,FALSE) -> Low income | J29: jdhabinshuti@gmail.com | K29: Pre-Conference + Main Congress | L29: 46207 | P29: Agree | Q29: 미등록
A30: 45860.797 | B30: Umuhoza Marie Claire | D30: Female | E30: 35013 | F30: Rwanda | G30: Public Hospital | H30: Junior Doctor | I30: =VLOOKUP(CLEAN(F30),'World Bank Categories'!$B$4:$C$220,2,FALSE) -> Low income | J30: umumariec1@gmail.com | K30: Main Congress Only | L30: July 1, July 2, July 3, July 4 | P30: Agree | Q30: 등록 | S30: Marie Claire Umuhoza | T30: 35013 | U30: umumariec1@gmail.com | V30: 생년월일 일치, 이메일 일치, 이름 유사도 100, 이름 토큰 포함
A31: 45860.808 | B31: MAOMBI Melanie | D31: Female | E31: 35285 | F31: Rwanda | G31: University of Rwanda | H31: Resident | I31: =VLOOKUP(CLEAN(F31),'World Bank Categories'!$B$4:$C$220,2,FALSE) -> Low income | J31: melaniemaombi@gmail.com | K31: Pre-Conference + Main Congress | L31: June 29, June 30, July 1, July 2, July 3, July 4 | M31: 1, BITEGETSIMANA GEDEON, male, husband | P31: Agree | Q31: 미등록
A32: 45860.823 | B32: Donath SINABUBARAGA | D32: Male | E32: 36362 | F32: Rwanda | G32: Rwanda Christian Medical and Dental Organization | H32: student | I32: =VLOOKUP(CLEAN(F32),'World Bank Categories'!$B$4:$C$220,2,FALSE) -> Low income | J32: dosinabubaraga@gmail.com | K32: Pre-Conference + Main Congress | L32: June 30, July 1, July 2, July 3, July 4 | P32: Agree | Q32: 미등록
A33: 45860.982 | B33: Ruvimbo Mutize | D33: Female | E33: 37253 | F33: Zimbabwe | G33: National University of Science and Technology (NUST) | H33: Student | I33: =VLOOKUP(CLEAN(F33),'World Bank Categories'!$B$4:$C$220,2,FALSE) -> Middle income | J33: mutizer28@gmail.com | K33: Main Congress Only | L33: June 30, July 1, July 2, July 3, July 4 | P33: Agree | Q33: 등록 | S33: Ruvimbo Mutize
A34: 45861.652 | B34: INGABIRE Emeline | D34: Female | E34: 36721 | F34: Rwanda | G34: Rwanda Christian Medical and Dental Organisation | H34: Student | I34: =VLOOKUP(CLEAN(F34),'World Bank Categories'!$B$4:$C$220,2,FALSE) -> Low income | J34: emelinerda@gmail.com | K34: Student Conference + Main Congress | L34: June 29, June 30, July 1, July 2, July 3, July 4 | P34: Agree | Q34: 미등록
A35: 45862.865 | B35: Unkwiye hertier | D35: Male | E35: 36536 | F35: Rwanda | G35: Rwanda Christian Medical and Dental Organization (RCMDO) | H35: President of Chritian medical student fellowship -Remera chapter | I35: =VLOOKUP(CLEAN(F35),'World Bank Categories'!$B$4:$C$220,2,FALSE) -> Low income | J35: hertierunkwiye1@gmail.com | K35: Main Congress Only | L35: June 30, July 1, July 2, July 3, July 4 | P35: Agree | Q35: 미등록
A36: 45862.937 | B36: BANA Keys Pamela | C36: Pamla Keys BANA | D36: Female | E36: 38542 | F36: Rwanda | G36: Rwanda Christian Medical and dental Organization | H36: Student | I36: =VLOOKUP(CLEAN(F36),'World Bank Categories'!$B$4:$C$220,2,FALSE) -> Low income | J36: kpamela210@gmail.com | K36: Student Conference + Main Congress | L36: June 29, June 30, July 1, July 2, July 3, July 4 | P36: Agree | Q36: 미등록
A37: 45865.161 | B37: MUTABARUKA John | D37: Male | E37: 45908 | F37: Rwanda | G37: Rwanda Christian Medical and Dental Organization. | H37: Student Leader | I37: =VLOOKUP(CLEAN(F37),'World Bank Categories'!$B$4:$C$220,2,FALSE) -> Low income | J37: mutabarukajohn250@gmail.com | K37: Pre-Conference + Main Congress | L37: June 29, June 30, July 1, July 2, July 3, July 4 | P37: Agree | Q37: 미등록
A38: 45865.165 | B38: KILACH CAROLE JESANG | D38: Female | E38: 32229 | F38: Kenya | G38: CHRISTIAN MEDICAL FELLOWSHIP- KENYA | H38: Dr/Miss/ Regional Leader | I38: =VLOOKUP(CLEAN(F38),'World Bank Categories'!$B$4:$C$220,2,FALSE) -> Middle income | J38: carolejesang@gmail.com | K38: Pre-Conference + Main Congress | L38: June 29, June 30, July 1, July 2, July 3, July 4 | P38: Agree | Q38: 등록 | R38: paid | S38: KILACH CAROLE JESANG | T38: 32229 | U38: carolejesang@gmail.com | V38: 생년월일 일치, 이메일 일치, 이름 완전일치
A39: 45865.819 | B39: Mugeni Adeline | D39: Female | E39: 28995 | F39: Rwanda | G39: Rwanda Christian Medical and Dental Organisation | H39: Dr | I39: =VLOOKUP(CLEAN(F39),'World Bank Categories'!$B$4:$C$220,2,FALSE) -> Low income | J39: mugenia23@gmail.com | K39: Pre-Conference + Main Congress | L39: June 29, June 30, July 1, July 2, July 3, July 4 | P39: Agree | Q39: 등록 | S39: Adeline Mugeni | T39: 28995 | U39: mugenia23@gmail.com | V39: 생년월일 일치, 이메일 일치, 이름 유사도 100, 이름 토큰 포함
A40: 45865.819 | B40: KANANGA Wilson | D40: Male | E40: 35647 | F40: Rwanda | G40: Nyamata level two Teaching Hospital | H40: Intern Doctor | I40: =VLOOKUP(CLEAN(F40),'World Bank Categories'!$B$4:$C$220,2,FALSE) -> Low income | J40: kanawilson01@gmail.com | K40: Pre-Conference + Main Congress | L40: June 30, July 1, July 2, July 3, July 4 | P40: Agree | Q40: 미등록
A41: 45866.256 | B41: BUTOYI Alphonse | C41: BUTOYI Alphonse | D41: Male | E41: 26966 | F41: Rwanda | G41: Legacy Clinics | H41: Senior consultant Obstetrician &Gyneacologist | I41: =VLOOKUP(CLEAN(F41),'World Bank Categories'!$B$4:$C$220,2,FALSE) -> Low income | J41: alphonse.butoyi@doctor.com | K41: Main Congress Only | L41: July 1, July 2, July 3, July 4 | P41: Agree | Q41: 미등록
A42: 45870.142 | B42: Aline Garcia Pereira | C42: Aline Garcia Pereira | D42: Female | E42: 32847 | F42: Brazil | G42: Uniasselvi (University)/ MDC -Medicos de Cristo | H42: I am student of Health Management (graduation). But I am also PHD | I42: =VLOOKUP(CLEAN(F42),'World Bank Categories'!$B$4:$C$220,2,FALSE) -> Middle income | J42: alinegpereira1@gmail.com | K42: Student Conference + Main Congress | L42: June 29, June 30, July 1, July 2, July 3, July 4 | P42: Agree | Q42: 등록 | R42: paid | S42: Aline Garcia Pereira | T42: 32847 | U42: alinegpereira1@gmail.com | V42: 생년월일 일치, 이메일 일치, 이름 완전일치
...

Sheet 무료숙소확정전체명단
A2: =COUNTA(B5:B14647) -> 576 | B2: 자원봉사자, 지원팀, 중국팀 등은 포함 안 된 인원 | C2: Godsends 등록자 수 | D2: =COUNTIF(Q5:Q711,"등록") -> 576 | F2: Godsends 미등록자 수 | G2: =COUNTIF(Q5:Q2647,"미등록") -> 0 | I2: paid 완료 | J2: =COUNTA(R5:R14647) -> 576
A4: Timestamp | B4: 1. Name As it appears on your passport | C4: 2. Name (Korean): | D4: 3. Gender: | E4: 4. Date of Birth: (MM-DD-YYYY) | F4: 5. Nationality As it appears on your passport | G4: 6. Affiliation School/Institution/Organization Name | H4: 7. Title/Position | I4: 8. World Bank Category Found on your Registration Tab | J4: 9. Email Address Must be the same email used for registration | K4: 10. ICMDA Event You Plan to Attend | L4: 11. Free Accommodation Request Dates | M4: 12. Accompanying Family Member(s)(Name/Gender/Relationship): Are you bringing family member(s)? If yes, please indicate how many will accompany you and provide their name, gender, and relationship (ex: 1, John Doe, male, husband, John_D@gmail.com) | N4: 동반자 전체 요악 | O4: 본인 포함 총 인원(가족 단위 경우만) | P4: 13. Consent for Personal Information Use I hereby consent to the collection and use of the personal information provided above for the purpose of evaluating my application for ICMDA free accommodation and for related communications. | Q4: 등록판정 | R4: Paid | S4: 매칭된 godsends 이름 | T4: 매칭된 godsends 생년월일 | U4: 매칭된 godsends 이메일 | V4: 판정 근거 | W4: Column 1
A5: 45841.453 | B5: Elisa Mabel Galeano Gamarra | D5: Female | E5: 35614 | F5: Paraguay | G5: in the process of having an association in Paraguay | H5: doctor | I5: =VLOOKUP(CLEAN(F5),'World Bank Categories'!$B$4:$C$220,2,FALSE) -> Middle income | J5: elisamedoficial@gmail.com | K5: Pre-Conference + Main Congress | L5: June 29, June 30, July 1, July 2, July 3, July 4 | P5: Agree | Q5: 등록 | R5: bursary | S5: Elisa Mabel Galeano Gamarra
A6: 45843.795 | B6: NZAME Yolande | D6: Female | E6: 21016 | F6: Gabon | G6: Gabon Medical Chrétien | H6: Membre | I6: =VLOOKUP(CLEAN(F6),'World Bank Categories'!$B$4:$C$220,2,FALSE) -> Middle income | J6: yolandenzame@gmail.com | K6: Main Congress Only | L6: June 29, June 30, July 1, July 2, July 3, July 4 | M6: Rebecca, féminin, fille, vierin.rebecca@hotmail.fr | N6: Rebecca [딸] | O6: 2명/ (자녀 1명) | P6: Agree | Q6: 등록 | R6: paid | S6: NZAME Yolande
A7: 45853.25 | B7: Blessings Dendere | D7: Female | E7: 36458 | F7: Zimbabwe | G7: Christian Medical Fellowship | H7: Doctor | I7: =VLOOKUP(CLEAN(F7),'World Bank Categories'!$B$4:$C$220,2,FALSE) -> Middle income | J7: blessingszd@gmail.com | K7: Pre-Conference + Main Congress | L7: June 29, June 30, July 1, July 2, July 3, July 4 | P7: Agree | Q7: 등록 | R7: bursary | S7: Blessings Dendere
A8: 45859.287 | B8: Muhumuza Ndamage Stephen | C8: Not Korean | D8: Male | E8: 29178 | F8: Rwanda | G8: Rwanda Christian Medical and Dental Organization | H8: Head of Rwanda Christian Medical and a Dental Organization | I8: =VLOOKUP(CLEAN(F8),'World Bank Categories'!$B$4:$C$220,2,FALSE) -> Low income | J8: stephen20130@gmail.com | K8: Student Conference + Main Congress | L8: 46207 | P8: Agree | Q8: 등록 | R8: bursary | S8: Muhumuza Ndamage Stephen | T8: 29178 | U8: stephen20130@gmail.com | V8: 생년월일 일치, 이메일 일치, 이름 완전일치
A9: 45865.165 | B9: KILACH CAROLE JESANG | D9: Female | E9: 32229 | F9: Kenya | G9: CHRISTIAN MEDICAL FELLOWSHIP- KENYA | H9: Dr/Miss/ Regional Leader | I9: =VLOOKUP(CLEAN(F9),'World Bank Categories'!$B$4:$C$220,2,FALSE) -> Middle income | J9: carolejesang@gmail.com | K9: Pre-Conference + Main Congress | L9: June 29, June 30, July 1, July 2, July 3, July 4 | P9: Agree | Q9: 등록 | R9: paid | S9: KILACH CAROLE JESANG | T9: 32229 | U9: carolejesang@gmail.com | V9: 생년월일 일치, 이메일 일치, 이름 완전일치
A10: 45870.142 | B10: Aline Garcia Pereira | C10: Aline Garcia Pereira | D10: Female | E10: 32847 | F10: Brazil | G10: Uniasselvi (University)/ MDC -Medicos de Cristo | H10: I am student of Health Management (graduation). But I am also PHD | I10: =VLOOKUP(CLEAN(F10),'World Bank Categories'!$B$4:$C$220,2,FALSE) -> Middle income | J10: alinegpereira1@gmail.com | K10: Student Conference + Main Congress | L10: June 29, June 30, July 1, July 2, July 3, July 4 | P10: Agree | Q10: 등록 | R10: paid | S10: Aline Garcia Pereira | T10: 32847 | U10: alinegpereira1@gmail.com | V10: 생년월일 일치, 이메일 일치, 이름 완전일치
A11: 45871.236 | B11: PAUL STEPHEN ATARO AYELLA | D11: Male | E11: 28186 | F11: Uganda | G11: ICMDA | H11: REGIONAL REPRESENTATIVE EAST AFRICA | I11: =VLOOKUP(CLEAN(F11),'World Bank Categories'!$B$4:$C$220,2,FALSE) -> Low income | J11: ATARODRPAPA@GMAIL.COM | K11: Student Conference + Main Congress | L11: June 29, June 30, July 1, July 2, July 3, July 4 | M11: ATARO JANE KARINA, FEMALE. ATARO NEEMA ANGIOLETTA, FEMALE DAUGHTERS | N11: ATARO JANE KARINA, FEMALE. ATARO NEEMA ANGIOLETTA, FEMALE DAUGHTERS 딸 2명 | O11: 3명/ (자녀 2명) | P11: Agree | Q11: 등록 | R11: bursary | S11: Paul Stephen Ataro Ayella | T11: 28186 | U11: atarodrpapa@gmail.com | V11: 생년월일 일치, 이메일 일치, 이름 완전일치
A12: 45874.23 | B12: Mugaba Proscovia Mujeere | D12: Female | E12: 28943 | F12: Uganda | G12: Uganda Christian Medical Fellowship (UCMF) | H12: Chairperson of UCMF National Executive Committee | I12: =VLOOKUP(CLEAN(F12),'World Bank Categories'!$B$4:$C$220,2,FALSE) -> Low income | J12: drprosiemm@gmail.com | K12: Main Congress Only | L12: June 30, July 1, July 2, July 3, July 4 | P12: Agree | Q12: 등록 | R12: bursary | S12: Proscovia Mujeere Mugaba
A13: 45875.633 | B13: Theodorus Hedwin Kadrianto | D13: Male | E13: 32327 | F13: Indonesia | G13: ICMDA | H13: AEO for East Asia, Southeast Asia, Oceania | I13: =VLOOKUP(CLEAN(F13),'World Bank Categories'!$B$4:$C$220,2,FALSE) -> Middle income | J13: theodorus.hedwin@icmda.net | K13: Pre-Conference + Main Congress | L13: June 29, June 30, July 1, July 2, July 3, July 4 | P13: Agree | Q13: 등록 | R13: paid | S13: Theodorus Hedwin Kadrianto | T13: 32327 | U13: theodorus.hedwin@icmda.net | V13: 생년월일 일치, 이메일 일치, 이름 완전일치
A14: 45883.567 | B14: PETER SATHIYANATHAN MICHEAL JOHN | D14: Male | E14: 28573 | F14: MALAYSIA | G14: HEALTHCARE CHRISTIAN FELLOWSHIP MALAYSIA | H14: DOCTOR | I14: =VLOOKUP(CLEAN(F14),'World Bank Categories'!$B$4:$C$220,2,FALSE) -> Middle income | J14: doctorpeter@hotmail.com | K14: Main Congress Only | L14: July 1, July 2, July 3, July 4 | M14: IRINE AARATHANA PETER SATHIYANATHAN, FEMALE, - 12 YEARS OLD DAUGHTER , doctorpeter@hotmail.com | N14: IRINE AARATHANA PETER SATHIYANATHAN [딸, 12세] | O14: 2명/ (자녀 1명) | P14: Agree | Q14: 등록 | R14: paid | S14: PETER SATHIYANATHAN MICHEAL JOHN | T14: 28573 | U14: doctorpeter@hotmail.com | V14: 생년월일 일치, 이메일 일치, 이름 완전일치
A15: 45890.989 | B15: Alina | D15: Female | E15: 36334 | F15: Belarus | G15: Belarussian CMF | H15: Ophtalmologist | I15: =VLOOKUP(CLEAN(F15),'World Bank Categories'!$B$4:$C$220,2,FALSE) -> Middle income | J15: kurdunap@gmail.com | K15: Main Congress Only | L15: June 29, June 30, July 1, July 2, July 3, July 4 | P15: Agree | Q15: 등록 | R15: bursary | S15: Alina Kurdun
A16: 45895.305 | B16: Semby, Johan Kyung Hwa | D16: Male | E16: 24127 | F16: Sweden | G16: Linköping University/Linköping University Hospital Department of Opthalmology/ ICMDA Sweden | H16: Senior Consultant in Ophthalmology/ Leader, organizer for the delegation from ICMDA Sweden and Finland | I16: =VLOOKUP(CLEAN(F16),'World Bank Categories'!$B$4:$C$220,2,FALSE) -> High income | J16: johan.semby@gmail.com | K16: Pre-Conference + Main Congress | L16: June 29, June 30, July 1, July 2, July 3, July 4 | M16: 1, Joshua Semby, male, son, joshua.semby7@gmail.com | N16: Joshua Semby [아들] | O16: 2명/ (자녀 1명) | P16: Agree | Q16: 등록 | R16: paid | S16: Johan Kyung Hwa Semby | T16: 24492 | U16: johan.semby@gmail.com | V16: 이메일 일치, 이름 유사도 100, 이름 토큰 포함
A17: 45900.026 | B17: NURGUL MAMYROVA | D17: Female | E17: 29297 | F17: Kyrgyz Republic | G17: ICMDA | H17: Doctor | I17: =VLOOKUP(CLEAN(F17),'World Bank Categories'!$B$4:$C$220,2,FALSE) -> Middle income | J17: nurgulicmda@gmail.com | K17: Student Conference + Main Congress | L17: June 29, June 30, July 1, July 2, July 3, July 4 | M17: Yes: Simon Peter Nadeem-my husband, My Daughter-Shulmiyat Sarah Nadeem, and my son -Timothy Simon Nadeem) | N17: Simon Peter Nadeem [배우자(남편)] Shulmiyat Sarah Nadeem[딸, 18세] Timothy Simon Nadeem [아들, 13세] | O17: 4명/ (자녀 2명, 배우자 1명) | P17: Agree | Q17: 등록 | R17: paid | S17: Nurgul Mamyrova | T17: 29297 | U17: nurgulicmda@gmail.com | V17: 생년월일 일치, 이메일 일치, 이름 완전일치
A18: 45908.782 | B18: Diana | C18: Safina | D18: Female | E18: 30253 | F18: Russian Federation | G18: ICMDA | H18: Regional representative, Eurasia training administrator | I18: =VLOOKUP(CLEAN(F18),'World Bank Categories'!$B$4:$C$220,2,FALSE) -> High income | J18: diana.safina316@gmail.com | K18: Pre-Conference + Main Congress | L18: June 29, June 30, July 1, July 2, July 3, July 4 | M18: Daria Safina, female, daughter 13 years old | N18: Daria Safina [딸, 13세] | O18: 2명/ (자녀 1명) | P18: Agree | Q18: 등록 | R18: bursary | S18: Diana Safina | T18: 30253 | U18: diana.safina316@gmail.com | V18: 생년월일 일치, 이메일 일치, 이름 유사도 100
A19: 45909.696 | B19: BENJAMIN DUBE | D19: Male | E19: 35302 | F19: ZIMBABWE | G19: NATIONAL UNIVERSITY OF SCIENCE AND TECHNOLOGY, ZIMBABWE | H19: Chairperson, NUST Christian Medical Fellowship (CMF) | I19: =VLOOKUP(CLEAN(F19),'World Bank Categories'!$B$4:$C$220,2,FALSE) -> Middle income | J19: benjiedube25@gmail.com | K19: Student Conference + Main Congress | L19: June 29, June 30, July 1, July 2, July 3, July 4 | P19: Agree | Q19: 등록 | R19: bursary | S19: DUBE BENJAMIN | T19: 35302 | U19: benjiedube25@gmail.com | V19: 생년월일 일치, 이메일 일치, 이름 유사도 100, 이름 토큰 포함
A20: 45918.29 | B20: Peter Fee | D20: Male | E20: 28989 | F20: United Kingdom | G20: Royal Belfast Children's Hospital, Belfast, UK | H20: Consultant Anaesthetist | I20: =VLOOKUP(CLEAN(F20),'World Bank Categories'!$B$4:$C$220,2,FALSE) -> High income | J20: peterfee@doctors.org.uk | K20: Pre-Conference + Main Congress | L20: June 29, June 30, July 1, July 2, July 3, July 4 | M20: 4: Kerry Fee, female, wife, thefees@me.com; Grace Fee, female, daughter; Joel Fee, male, son; Toby Fee, male, son. | N20: Kerry Fee [배우자(아내)] thefees@me.com Grace Fee [딸, 12세] Joel Fee [아들, 14세] Toby Fee [아들, 10세] | O20: 5명/ (자녀 3명, 배우자 1명) | P20: Agree | Q20: 등록 | R20: paid | S20: Peter Fee | T20: 28989 | U20: peterfee@doctors.org.uk | V20: 생년월일 일치, 이메일 일치, 이름 완전일치
A21: 45918.575 | B21: Nakanjako | C21: Sharon | D21: Female | E21: 34006 | F21: Uganda | G21: Uganda Christian medical Fellowship | H21: Clinical psychologist | I21: =VLOOKUP(CLEAN(#REF!),'World Bank Categories'!$B$4:$C$220,2,FALSE) -> #REF! | J21: sharonnakanjako2023@gmail.com | K21: Pre-Conference + Main Congress | L21: June 29, June 30, July 1, July 2, July 3, July 4 | P21: Agree | Q21: 등록 | R21: bursary | S21: Sharon Nakanjako | T21: 34006 | U21: sharonnakanjako2023@gmail.com | V21: 생년월일 일치, 이메일 일치, 이름 유사도 100
A22: 45922.815 | B22: Greta Gamal Nazir Kross | D22: Female | E22: 30328 | F22: Egypt, Arab Rep. | G22: Cmf egypt | H22: Pediatric specialist (director of operations of cmf egypt) | I22: =VLOOKUP(CLEAN(F22),'World Bank Categories'!$B$4:$C$220,2,FALSE) -> Middle income | J22: gretagamal@hotmail.com | K22: Pre-Conference + Main Congress | L22: June 29, June 30, July 1, July 2, July 3, July 4 | M22: George robile,male,husband Jason george,male ,son Jenny george,female,daughter | N22: George robile [배우자(남편)] gretagamal@hotmail.com Jason george [아들, 13세] Jenny george [딸, 17세] | O22: 4명/ (자녀 2명, 배우자 1명) | P22: Agree | Q22: 등록 | R22: bursary | S22: Greta Gamal
A23: 45927.904 | B23: Christa Adeline | D23: Female | E23: 35457 | F23: Indonesia | G23: ICMDA | H23: Regional Representative for Southeast Asia | I23: =VLOOKUP(CLEAN(F23),'World Bank Categories'!$B$4:$C$220,2,FALSE) -> Middle income | J23: christa.adeline@icmda.net | K23: Pre-Conference + Main Congress | L23: June 30, July 1, July 2, July 3, July 4 | P23: Agree | Q23: 등록 | R23: paid | S23: Christa Adeline | T23: 35457 | U23: christa.adeline@icmda.net | V23: 생년월일 일치, 이메일 일치, 이름 완전일치
A24: 45927.984 | B24: Quacy Asheeke Grant | D24: Male | E24: 31257 | F24: Guyana | G24: Lausanne Movement Caribbean/ICMDA Guyana-Caribbean | H24: Regional Director (Lausanne Movement Caribbean) | I24: =VLOOKUP(CLEAN(F24),'World Bank Categories'!$B$4:$C$220,2,FALSE) -> High income | J24: qgrant@lausanne.org | K24: Main Congress Only | L24: June 29, June 30, July 1, July 2, July 3, July 4 | P24: Agree | Q24: 등록 | R24: bursary | S24: Quacy Asheeke Grant
A25: 45928.771 | B25: LOUIE BENJAMIN KWON BOU | D25: Male | E25: 38475 | F25: NEW ZEALAND | G25: University of Otago | H25: Medical Student | I25: =VLOOKUP(CLEAN(F25),'World Bank Categories'!$B$4:$C$220,2,FALSE) -> High income | J25: bklouie@outlook.com | K25: Pre-Conference + Main Congress | L25: June 29, June 30, July 1, July 2, July 3 | M25: 1, Yidao Chua, male, friend, yidaochua@gmail.com | P25: Agree | Q25: 등록 | R25: paid | S25: Benjamin Louie | T25: 38475 | U25: bklouie@outlook.com | V25: 생년월일 일치, 이메일 일치, 이름 유사도 100, 이름 토큰 포함
A26: 45929.067 | B26: Mohalenyane Matheko Mary | D26: Female | E26: 35435 | F26: Lesotho | G26: Senkatana Oncology Clinic | H26: Dr. | I26: =VLOOKUP(CLEAN(F26),'World Bank Categories'!$B$4:$C$220,2,FALSE) -> Middle income | J26: matheko.mohalenyane@gmail.com | K26: Pre-Conference + Main Congress | L26: June 29, June 30, July 1, July 2, July 3, July 4 | P26: Agree | Q26: 등록 | R26: bursary | S26: Matheko Mohalenyane | T26: 35435 | U26: matheko.mohalenyane@yahoo.com | V26: 생년월일 일치, 이름 유사도 100, 이름 토큰 포함
A27: 45930.648 | B27: Anitha David | D27: Female | E27: 25119 | F27: India | G27: Emmanuel Hospital Association | H27: Dentist | I27: =VLOOKUP(CLEAN(F27),'World Bank Categories'!$B$4:$C$220,2,FALSE) -> Middle income | J27: Anitha.David@icmda.net | K27: Pre-Conference + Main Congress | L27: June 29, June 30, July 1, July 2, July 3, July 4 | P27: Agree | Q27: 등록 | R27: bursary | S27: Anitha David | T27: 25119 | U27: Anitha.David@imcda.net
A28: 45932.036 | B28: Abiyu Tadesse Fulea | C28: Kim | D28: Male | E28: 31339 | F28: Ethiopia | G28: CMF Ethiopia | H28: CMF Ethiopia chairperson | I28: =VLOOKUP(CLEAN(F28),'World Bank Categories'!$B$4:$C$220,2,FALSE) -> Low income | J28: martabiyju@gmail.com | K28: Pre-Conference + Main Congress | L28: June 29, June 30, July 1, July 2, July 3, July 4 | P28: Agree | Q28: 등록 | R28: bursary | S28: Abiyu Tadesse Fulea | T28: 31339 | U28: martabiyju@gmail.com | V28: 생년월일 일치, 이메일 일치, 이름 완전일치
A29: 45933.674 | B29: Kezia Christina Viani Wijaya | C29: 케지아 크리스티나 비아니 위자야 | D29: Female | E29: 36659 | F29: Indonesia | G29: CMDA Indonesia | H29: Member | I29: =VLOOKUP(CLEAN(F29),'World Bank Categories'!$B$4:$C$220,2,FALSE) -> Middle income | J29: keziawij@gmail.com | K29: Main Congress Only | L29: July 1, July 2, July 3, July 4 | P29: Agree | Q29: 등록 | R29: bursary | S29: Kezia Christina Viani Wijaya | T29: 36659 | U29: keziawij@gmail.com | V29: 생년월일 일치, 이메일 일치, 이름 완전일치
A30: 45943.156 | B30: Enimil Anthony Kwame | D30: Male | E30: 26224 | F30: Ghana | G30: Kwame Nkrumah University of Science and Technology | H30: Professor/Lecturer | I30: =VLOOKUP(CLEAN(F30),'World Bank Categories'!$B$4:$C$220,2,FALSE) -> Middle income | J30: Tonash@gmail.com | K30: Pre-Conference + Main Congress | L30: June 29, June 30, July 1, July 2, July 3, July 4 | M30: Helena Enimil, Female , Spouse | P30: Agree | Q30: 등록 | R30: Paid | S30: Anthony Enimil | T30: 26224 | U30: tonash@gmail.com | V30: 생년월일 일치, 이메일 일치, 이름 유사도 100, 이름 토큰 포함
A31: 45946.597 | B31: Alina Istrati | D31: Female | E31: 37372 | F31: Romania | G31: Nicolae Testemiţanu Moldova State University of Medicine and Pharmacy | H31: Student | I31: =VLOOKUP(CLEAN(F31),'World Bank Categories'!$B$4:$C$220,2,FALSE) -> High income | J31: istratialina16@gmail.com | K31: Pre-Conference + Main Congress | L31: June 29, June 30, July 1, July 2, July 3, July 4 | P31: Agree | Q31: 등록 | R31: bursary | S31: Istrati Alina | T31: 37372 | U31: istratialina16@gmail.com | V31: 생년월일 일치, 이메일 일치, 이름 유사도 100, 이름 토큰 포함
A32: 45947.179 | B32: HERVE TISTOU HITIMANA | D32: Male | E32: 33297 | F32: Burundi | G32: BCMDA | H32: Dr | I32: =VLOOKUP(CLEAN(F32),'World Bank Categories'!$B$4:$C$220,2,FALSE) -> Low income | J32: h.tistou@gmail.com | K32: Pre-Conference + Main Congress | L32: June 29, June 30, July 1, July 2, July 3, July 4 | P32: Agree | Q32: 등록 | R32: bursary | S32: HERVE TISTOU HITIMANA | T32: 33297 | U32: h.tistou@gmail.com | V32: 생년월일 일치, 이메일 일치, 이름 완전일치
A33: 45947.313 | B33: OKONGO BERFINA | D33: Female | E33: 36417 | F33: Senegal | G33: Association des médecins et dentistes chrétiens du Sénégal | H33: Treasury | I33: =VLOOKUP(CLEAN(F33),'World Bank Categories'!$B$4:$C$220,2,FALSE) -> Middle income | J33: O.berfina1@gmail.com | K33: Pre-Conference + Main Congress | L33: June 29, June 30, July 1, July 2, July 3, July 4 | P33: Agree | Q33: 등록 | R33: bursary | S33: OKONGO Berfina | T33: 36417 | U33: O.berfina1@gmail.com | V33: 생년월일 일치, 이메일 일치, 이름 완전일치
A34: 45947.313 | B34: ADONONSI FEGNITI MAHUTON MARIELLE | D34: Female | E34: 37086 | F34: Benin | G34: Association des Médecins et Dentistes Chrétiens du Sénégal | H34: Student leader | I34: =VLOOKUP(CLEAN(F34),'World Bank Categories'!$B$4:$C$220,2,FALSE) -> Middle income | J34: mariellehy@gmail.com | K34: Pre-Conference + Main Congress | L34: June 29, June 30, July 1, July 2, July 3, July 4 | P34: Agree | Q34: 등록 | R34: bursary | S34: Marielle Adononsi | T34: 37086 | U34: mariellehy@gmail.com | V34: 생년월일 일치, 이메일 일치, 이름 유사도 100, 이름 토큰 포함
A35: 45947.313 | B35: Rebecca Biaye | D35: Female | E35: 33994 | F35: Senegal | G35: Association des médecins et dentistes chrétiens du Sénégal | H35: National president | I35: =VLOOKUP(CLEAN(F35),'World Bank Categories'!$B$4:$C$220,2,FALSE) -> Middle income | J35: rebiaye@gmail.com | K35: Pre-Conference + Main Congress | L35: June 29, June 30, July 1, July 2, July 3, July 4 | P35: Agree | Q35: 등록 | R35: bursary | S35: Rebecca Biaye | T35: 33994 | U35: rebiaye@gmail.com | V35: 생년월일 일치, 이메일 일치, 이름 완전일치
A36: 45948.297 | B36: OBO Yapo Gilles | D36: Male | E36: 34126 | F36: Côte d’Ivoire | G36: AMPCI | H36: Medical Officer | I36: =VLOOKUP(CLEAN(F36),'World Bank Categories'!$B$4:$C$220,2,FALSE) -> Middle income | J36: yapogilles@yahoo.fr | K36: Pre-Conference + Main Congress | L36: June 29, June 30, July 1, July 2, July 3, July 4 | P36: Agree | Q36: 등록 | R36: bursary | S36: OBO Yapo Gilles | T36: 34126 | U36: yapogilles@yahoo.fr | V36: 생년월일 일치, 이메일 일치, 이름 완전일치
A37: 45948.8 | B37: Nermin Botros Zakaria Gohar | C37: 네르민 | D37: Female | E37: 34099 | F37: Egypt, Arab Rep. | G37: Faculty of medicine menofia university | H37: Assistant lecturer | I37: =VLOOKUP(CLEAN(F37),'World Bank Categories'!$B$4:$C$220,2,FALSE) -> Middle income | J37: nermenbotros22@gmail.com | K37: Pre-Conference + Main Congress | L37: June 29, June 30, July 1, July 2, July 3, July 4 | P37: Agree | Q37: 등록 | R37: bursary | S37: Nermin botros zakaria | T37: 34099 | U37: nermenbotros22@gmail.com | V37: 생년월일 일치, 이메일 일치, 이름 유사도 100, 이름 토큰 포함
A38: 45949.129 | B38: Nancy Botros Zakria Gohar | D38: Female | E38: 36381 | F38: Egypt, Arab Rep. | G38: Benha university hospital | H38: Cardiothoracic surgery resident | I38: =VLOOKUP(CLEAN(F38),'World Bank Categories'!$B$4:$C$220,2,FALSE) -> Middle income | J38: nancybotros161@gmail.com | K38: Pre-Conference + Main Congress | L38: June 29, June 30, July 1, July 2, July 3, July 4 | P38: Agree | Q38: 등록 | R38: bursary | S38: Nancy Botros Zakria Gohar | T38: 36381 | U38: nancybotros161@gmail.com | V38: 생년월일 일치, 이메일 일치, 이름 완전일치
A39: 45949.232 | B39: Bodoua Adjo Anne-Mireille | D39: Female | E39: 37412 | F39: Côte d’Ivoire | G39: AMPCI | H39: Medical student | I39: =VLOOKUP(CLEAN(F39),'World Bank Categories'!$B$4:$C$220,2,FALSE) -> Middle income | J39: bodouaanno@gmail.com | K39: Pre-Conference + Main Congress | L39: June 29, June 30, July 1, July 2, July 3, July 4 | P39: Agree | Q39: 등록 | R39: bursary | S39: Bodoua Adjo Anne-Mireille | T39: 37412 | U39: bodouaanno@gmail.com | V39: 생년월일 일치, 이메일 일치, 이름 완전일치
A40: 45950.126 | B40: Kupualor David Akwafo | D40: Male | E40: 28979 | F40: Ghana | G40: University of Ghana Medical Centre/St Joseph Hospital, Koforidua | H40: Senior Specialist | I40: =VLOOKUP(CLEAN(F40),'World Bank Categories'!$B$4:$C$220,2,FALSE) -> Middle income | J40: dkupualor@yahoo.com | K40: Pre-Conference + Main Congress | L40: June 29, June 30, July 1, July 2, July 3, July 4 | M40: Mrs Sarah Kupualor, Wife, marsar.asaa@yahoo.com | P40: Agree | Q40: 등록 | R40: paid | S40: David Akwafo Kupualor | T40: 28979 | U40: dkupualor@yahoo.com | V40: 생년월일 일치, 이메일 일치, 이름 유사도 100, 이름 토큰 포함
A41: 45950.134 | B41: Uhunmwangho Courage Ukponmwan | D41: Male | E41: 27390 | F41: Nigeria | G41: ICMDA West Africa | H41: Regional Secretary | I41: =VLOOKUP(CLEAN(F41),'World Bank Categories'!$B$4:$C$220,2,FALSE) -> Middle income | J41: ucourage@yahoo.com | K41: Pre-Conference + Main Congress | L41: June 29, June 30, July 1, July 2, July 3, July 4 | P41: Agree | Q41: 등록 | R41: bursary | S41: Courage Uhunmwangho | T41: 27390 | U41: ucourage@yahoo.com | V41: 생년월일 일치, 이메일 일치, 이름 유사도 100, 이름 토큰 포함
A42: 45951.22 | B42: IKEUBA DELIGHT CHIDEBELU | C42: Delight | D42: Male | E42: 38579 | F42: Nigeria | G42: Christian Medical and Dental Association | H42: Mr. | I42: =VLOOKUP(CLEAN(F42),'World Bank Categories'!$B$4:$C$220,2,FALSE) -> Middle income | J42: delightikeuba@gmail.com | K42: Pre-Conference + Main Congress | L42: June 30, July 1, July 2, July 3, July 4 | P42: Agree | Q42: 등록 | R42: bursary | S42: IKEUBA DELIGHT CHIDEBELU | T42: 38579 | U42: delightikeuba@gmail.com | V42: 생년월일 일치, 이메일 일치, 이름 완전일치
...

Sheet 가족단위명단
A2: 2인 가족 | B2: 3인 가족 | C2: 4인 가족 | D2: 5인 가족 | E2: 6인 가족 | F2: 합계
A3: =A4/2 -> 11 | B3: =B4/3 -> 7 | C3: =C4/4 -> 7 | D3: =D4/5 -> 1 | E3: =E4/6 -> 1 | F3: =SUM(A3:E3) -> 27 | G3: 가족 총 팀 수
A4: =SUMIF(P8:P1000,2) -> 22 | B4: =SUMIF(P8:P1000,3) -> 21 | C4: =SUMIF(P8:P1000,4) -> 28 | D4: =SUMIF(P8:P1000,5) -> 5 | E4: =SUMIF(P8:P1000,6) -> 6 | F4: =SUM(A4:E4) -> 82 | G4: 가족 총 인원 수
A6: =F4 -> 82
A8: Timestamp | B8: 1. Name As it appears on your passport | C8: 2. Name (Korean): | D8: 3. Gender: | E8: 4. Date of Birth: (MM-DD-YYYY) | F8: 5. Nationality As it appears on your passport | G8: 6. Affiliation School/Institution/Organization Name | H8: 7. Title/Position | I8: 8. World Bank Category Found on your Registration Tab | J8: 9. Email Address Must be the same email used for registration | K8: 10. ICMDA Event You Plan to Attend | L8: 11. Free Accommodation Request Dates | M8: 12. Accompanying Family Member(s)(Name/Gender/Relationship): Are you bringing family member(s)? If yes, please indicate how many will accompany you and provide their name, gender, and relationship (ex: 1, John Doe, male, husband, John_D@gmail.com) | N8: 동반자 전체 요악 | O8: 본인 포함 총 인원(가족 단위 경우만) | P8: 인원명 | Q8: 13. Consent for Personal Information Use I hereby consent to the collection and use of the personal information provided above for the purpose of evaluating my application for ICMDA free accommodation and for related communications. | R8: 등록판정 | S8: Paid | T8: 매칭된 godsends 이름 | U8: 매칭된 godsends 생년월일 | V8: 매칭된 godsends 이메일 | W8: 판정 근거 | X8: Column 1
A9: 45843.795 | B9: NZAME Yolande | D9: Female | E9: 21016 | F9: Gabon | G9: Gabon Medical Chrétien | H9: Membre | I9: =VLOOKUP(CLEAN(F9),'World Bank Categories'!$B$4:$C$220,2,FALSE) -> Middle income | J9: yolandenzame@gmail.com | K9: Main Congress Only | L9: June 29, June 30, July 1, July 2, July 3, July 4 | M9: Rebecca, féminin, fille, vierin.rebecca@hotmail.fr | N9: Rebecca [딸] | O9: 2명/ (자녀 1명) | P9: =VALUE(LEFT(O9,1)) -> 2 | Q9: Agree | R9: 등록 | S9: paid | T9: NZAME Yolande
A10: 45871.236 | B10: PAUL STEPHEN ATARO AYELLA | D10: Male | E10: 28186 | F10: Uganda | G10: ICMDA | H10: REGIONAL REPRESENTATIVE EAST AFRICA | I10: =VLOOKUP(CLEAN(F10),'World Bank Categories'!$B$4:$C$220,2,FALSE) -> Low income | J10: ATARODRPAPA@GMAIL.COM | K10: Student Conference + Main Congress | L10: June 29, June 30, July 1, July 2, July 3, July 4 | M10: ATARO JANE KARINA, FEMALE. ATARO NEEMA ANGIOLETTA, FEMALE DAUGHTERS | N10: ATARO JANE KARINA, FEMALE. ATARO NEEMA ANGIOLETTA, FEMALE DAUGHTERS 딸 2명 | O10: 3명/ (자녀 2명) | P10: =VALUE(LEFT(O10,1)) -> 3 | Q10: Agree | R10: 등록 | S10: bursary | T10: Paul Stephen Ataro Ayella | U10: 28186 | V10: atarodrpapa@gmail.com | W10: 생년월일 일치, 이메일 일치, 이름 완전일치
A11: 45883.567 | B11: PETER SATHIYANATHAN MICHEAL JOHN | D11: Male | E11: 28573 | F11: MALAYSIA | G11: HEALTHCARE CHRISTIAN FELLOWSHIP MALAYSIA | H11: DOCTOR | I11: =VLOOKUP(CLEAN(F11),'World Bank Categories'!$B$4:$C$220,2,FALSE) -> Middle income | J11: doctorpeter@hotmail.com | K11: Main Congress Only | L11: July 1, July 2, July 3, July 4 | M11: IRINE AARATHANA PETER SATHIYANATHAN, FEMALE, - 12 YEARS OLD DAUGHTER , doctorpeter@hotmail.com | N11: IRINE AARATHANA PETER SATHIYANATHAN [딸, 12세] | O11: 2명/ (자녀 1명) | P11: =VALUE(LEFT(O11,1)) -> 2 | Q11: Agree | R11: 등록 | S11: paid | T11: PETER SATHIYANATHAN MICHEAL JOHN | U11: 28573 | V11: doctorpeter@hotmail.com | W11: 생년월일 일치, 이메일 일치, 이름 완전일치
A12: 45895.305 | B12: Semby, Johan Kyung Hwa | D12: Male | E12: 24127 | F12: Sweden | G12: Linköping University/Linköping University Hospital Department of Opthalmology/ ICMDA Sweden | H12: Senior Consultant in Ophthalmology/ Leader, organizer for the delegation from ICMDA Sweden and Finland | I12: =VLOOKUP(CLEAN(F12),'World Bank Categories'!$B$4:$C$220,2,FALSE) -> High income | J12: johan.semby@gmail.com | K12: Pre-Conference + Main Congress | L12: June 29, June 30, July 1, July 2, July 3, July 4 | M12: 1, Joshua Semby, male, son, joshua.semby7@gmail.com | N12: Joshua Semby [아들] | O12: 2명/ (자녀 1명) | P12: =VALUE(LEFT(O12,1)) -> 2 | Q12: Agree | R12: 등록 | S12: paid | T12: Johan Kyung Hwa Semby | U12: 24492 | V12: johan.semby@gmail.com | W12: 이메일 일치, 이름 유사도 100, 이름 토큰 포함
A13: 45900.026 | B13: NURGUL MAMYROVA | D13: Female | E13: 29297 | F13: Kyrgyz Republic | G13: ICMDA | H13: Doctor | I13: =VLOOKUP(CLEAN(F13),'World Bank Categories'!$B$4:$C$220,2,FALSE) -> Middle income | J13: nurgulicmda@gmail.com | K13: Student Conference + Main Congress | L13: June 29, June 30, July 1, July 2, July 3, July 4 | M13: Yes: Simon Peter Nadeem-my husband, My Daughter-Shulmiyat Sarah Nadeem, and my son -Timothy Simon Nadeem) | N13: Simon Peter Nadeem [배우자(남편)] Shulmiyat Sarah Nadeem[딸, 18세] Timothy Simon Nadeem [아들, 13세] | O13: 4명/ (자녀 2명, 배우자 1명) | P13: =VALUE(LEFT(O13,1)) -> 4 | Q13: Agree | R13: 등록 | S13: paid | T13: Nurgul Mamyrova | U13: 29297 | V13: nurgulicmda@gmail.com | W13: 생년월일 일치, 이메일 일치, 이름 완전일치
A14: 45908.782 | B14: Diana | C14: Safina | D14: Female | E14: 30253 | F14: Russian Federation | G14: ICMDA | H14: Regional representative, Eurasia training administrator | I14: =VLOOKUP(CLEAN(F14),'World Bank Categories'!$B$4:$C$220,2,FALSE) -> High income | J14: diana.safina316@gmail.com | K14: Pre-Conference + Main Congress | L14: June 29, June 30, July 1, July 2, July 3, July 4 | M14: Daria Safina, female, daughter 13 years old | N14: Daria Safina [딸, 13세] | O14: 2명/ (자녀 1명) | P14: =VALUE(LEFT(O14,1)) -> 2 | Q14: Agree | R14: 등록 | S14: bursary | T14: Diana Safina | U14: 30253 | V14: diana.safina316@gmail.com | W14: 생년월일 일치, 이메일 일치, 이름 유사도 100
A15: 45918.29 | B15: Peter Fee | D15: Male | E15: 28989 | F15: United Kingdom | G15: Royal Belfast Children's Hospital, Belfast, UK | H15: Consultant Anaesthetist | I15: =VLOOKUP(CLEAN(F15),'World Bank Categories'!$B$4:$C$220,2,FALSE) -> High income | J15: peterfee@doctors.org.uk | K15: Pre-Conference + Main Congress | L15: June 29, June 30, July 1, July 2, July 3, July 4 | M15: 4: Kerry Fee, female, wife, thefees@me.com; Grace Fee, female, daughter; Joel Fee, male, son; Toby Fee, male, son. | N15: Kerry Fee [배우자(아내)] thefees@me.com Grace Fee [딸, 12세] Joel Fee [아들, 14세] Toby Fee [아들, 10세] | O15: 5명/ (자녀 3명, 배우자 1명) | P15: =VALUE(LEFT(O15,1)) -> 5 | Q15: Agree | R15: 등록 | S15: paid | T15: Peter Fee | U15: 28989 | V15: peterfee@doctors.org.uk | W15: 생년월일 일치, 이메일 일치, 이름 완전일치
A16: 45922.815 | B16: Greta Gamal Nazir Kross | D16: Female | E16: 30328 | F16: Egypt, Arab Rep. | G16: Cmf egypt | H16: Pediatric specialist (director of operations of cmf egypt) | I16: =VLOOKUP(CLEAN(F16),'World Bank Categories'!$B$4:$C$220,2,FALSE) -> Middle income | J16: gretagamal@hotmail.com | K16: Pre-Conference + Main Congress | L16: June 29, June 30, July 1, July 2, July 3, July 4 | M16: George robile,male,husband Jason george,male ,son Jenny george,female,daughter | N16: George robile [배우자(남편)] gretagamal@hotmail.com Jason george [아들, 13세] Jenny george [딸, 17세] | O16: 4명/ (자녀 2명, 배우자 1명) | P16: =VALUE(LEFT(O16,1)) -> 4 | Q16: Agree | R16: 등록 | S16: bursary | T16: Greta Gamal
A17: 45984.987 | B17: MASRA NGARMBAYE | D17: Male | E17: 31065 | F17: Chad | G17: ASSOCIATION DES MEDECINS ET DENTISTES CHRETIENS DU TCHAD- AMDCT | H17: DOCTOR MEMBER | I17: =VLOOKUP(CLEAN(F17),'World Bank Categories'!$B$4:$C$220,2,FALSE) -> Low income | J17: nmasra@yahoo.com | K17: Pre-Conference + Main Congress | L17: June 29, June 30, July 1, July 2, July 3, July 4 | M17: 1, Edith Dekoum Nelembaye, female, Wife, nmasra@yahoo.com 2, Manaseth Toulaboua Ngarmbaye, male, Son, nmasra@yahoo.com | N17: Edith Dekoum Nelembaye [배우자(아내)] Manaseth Toulaboua Ngarmbaye [아들, 2세] | O17: 3명/ (자녀 1명, 배우자 1명) | P17: =VALUE(LEFT(O17,1)) -> 3 | Q17: Agree | R17: 등록 | S17: bursary | T17: MASRA NGARMBAYE | U17: 31065 | V17: nmasra@yahoo.com | W17: 생년월일 일치, 이메일 일치, 이름 완전일치
A18: 45989.19 | B18: Sofako Améganvi EGLOH | D18: Male | E18: 29659 | F18: TOGO | G18: CMF TOGO | H18: Doctor | I18: =VLOOKUP(CLEAN(F18),'World Bank Categories'!$B$4:$C$220,2,FALSE) -> Low income | J18: esofak81@gmail.com | K18: Pre-Conference + Main Congress | L18: June 29, June 30, July 1, July 2, July 3, July 4 | M18: 1, Afi Kafui BANIBA ATOKO Epse EGLOH, Female, Spouse, kbaniba@gmail.com 2, Betsaleel Ewousika Améganvi EGLOH, Male, Child, esofak81@gmail.com | N18: Afi Kafui BANIBA ATOKO Epse EGLOH [배우자(아내)] Betsaleel Ewousika Améganvi EGLOH [자녀, 3세] | O18: 3명/ (자녀 1명, 배우자 1명) | P18: =VALUE(LEFT(O18,1)) -> 3 | Q18: Agree | R18: 등록 | S18: bursary | T18: Améganvi Sofako EGLOH | U18: 29659 | V18: esofak81@gmail.com | W18: 생년월일 일치, 이메일 일치, 이름 유사도 100, 이름 토큰 포함
A19: 45996.041 | B19: TRAY CHEAVKUN | D19: Male | E19: 32733 | F19: Cambodia | G19: Cambodian Christian Medical Fellowship | H19: Member | I19: =VLOOKUP(CLEAN(F19),'World Bank Categories'!$B$4:$C$220,2,FALSE) -> Middle income | J19: traykun@live.com | K19: Main Congress Only | L19: July 2, July 3, July 4 | M19: Yes my family, ANG SREYNIN, Female, wife, angsreynin@gmail.com and one daughter 3years old female. | N19: ANG SREYNIN [배우자(아내)] one daughter [딸, 3세] | O19: 3명/ (자녀 1명, 배우자 1명) | P19: =VALUE(LEFT(O19,1)) -> 3 | Q19: Agree | R19: 등록 | S19: bursary | T19: TRAY CHEAVKUN | U19: 32733 | V19: traykun@live.com | W19: 생년월일 일치, 이메일 일치, 이름 완전일치
A20: 46012.652 | B20: Gena kerollos dawood gerges | D20: Female | E20: 32980 | F20: Egypt, Arab Rep. | G20: CMF | H20: ENT specialist | I20: =VLOOKUP(CLEAN(F20),'World Bank Categories'!$B$4:$C$220,2,FALSE) -> Middle income | J20: genakerollos@gmail.com | K20: Pre-Conference + Main Congress | L20: June 29, June 30, July 1, July 2, July 3, July 4 | M20: Ramy nabil, male , husband, ramyzakharious@gmail.com + holy ramy, female , daughter, 11 years old + heaven ramy, female, daughter, 6 years old | N20: Ramy nabil [배우자(남편)] holy ramy [딸, 11세] heaven ramy [딸, 6세] | O20: 4명/ (자녀 2명, 배우자 1명) | P20: =VALUE(LEFT(O20,1)) -> 4 | Q20: Agree | R20: 등록 | S20: bursary | T20: Gena kerollos dawood gerges | U20: 32980 | V20: genakerollos@gmail.com | W20: 생년월일 일치, 이메일 일치, 이름 완전일치
A21: 46013.749 | B21: Donald Kafa | D21: Male | E21: 28068 | F21: Solomon Islands | G21: Oceania ICMDA | H21: Medical Doctor | I21: =VLOOKUP(CLEAN(F21),'World Bank Categories'!$B$4:$C$220,2,FALSE) -> Middle income | J21: kafadonald@gmail.com | K21: Pre-Conference + Main Congress | L21: June 29, June 30, July 1 | M21: Elnisha Donald Kafa, 13 year old Son, email: kafadonald@gmail.com | N21: Elnisha Donald Kafa [아들, 13세] | O21: 2명/ (자녀 1명) | P21: =VALUE(LEFT(O21,1)) -> 2 | Q21: Agree | R21: 등록 | S21: bursary | T21: Donald Kafa | U21: 28068 | V21: kafadonald@gmail.com | W21: 생년월일 일치, 이메일 일치, 이름 완전일치
A22: 46021.99 | B22: Priscilia Pratami Intan | D22: Female | E22: 33794 | F22: Indonesia | G22: CMDFI | H22: Saline Process Teamwork | I22: =VLOOKUP(CLEAN(F22),'World Bank Categories'!$B$4:$C$220,2,FALSE) -> Middle income | J22: priscilia.pratami.intan@gmail.com | K22: Pre-Conference + Main Congress | L22: June 29, June 30, July 1, July 2, July 3, July 4 | M22: 3, Rudy. S, male, husband, rudisetiawan883@gmail.com; Kara Jessica Joetan, female, daughter, priscilia.pratami.intan@gmail.com; Anya Kirana Joetan, female, daughter, priscilia.pratami.intan@gmail.com | N22: Rudy.S [배우자(남편)] Kara Jessica Joetan [딸, 3세] Anya Kirana Joetan [딸] | O22: 4명/ (자녀 2명, 배우자 1명) | P22: =VALUE(LEFT(O22,1)) -> 4 | Q22: Agree | R22: 등록 | S22: bursary | T22: Priscilia Pratami Intan | U22: 33794 | V22: priscilia.pratami.intan@gmail.com | W22: 생년월일 일치, 이메일 일치, 이름 완전일치
A23: 46022.752 | B23: PHOEM | C23: CHANTHEN | D23: Female | E23: 33802 | F23: Cambodia | G23: Cambodian Chrsitian Medical Fellowship | H23: Key Volunteer | I23: =VLOOKUP(CLEAN(F23),'World Bank Categories'!$B$4:$C$220,2,FALSE) -> Middle income | J23: drsam0701@gmail.com | K23: Main Congress Only | L23: July 1, July 2, July 3, July 4 | M23: yes, Limeng Lichi, female, Daughter, drsam0701@gmail.com | N23: Limeng Lichi [딸, 16세] | O23: 2명/ (자녀 1명) | P23: =VALUE(LEFT(O23,1)) -> 2 | Q23: Agree | R23: 등록 | S23: bursary | T23: Phoem Chanthen | U23: 33802 | V23: drsam0701@gmail.com | W23: 생년월일 일치, 이메일 일치, 이름 유사도 100
A24: 46023.099 | B24: Rani Dwi Cahyaniputri | D24: Female | E24: 31644 | F24: Indonesia | G24: Simore Ministry | H24: Director | I24: =VLOOKUP(CLEAN(F24),'World Bank Categories'!$B$4:$C$220,2,FALSE) -> Middle income | J24: rk.tulung@gmail.com | K24: Main Congress Only | L24: June 29, June 30, July 1, July 2, July 3, July 4 | M24: 2, Augustine Elizabeth Pattipeilohy/female/mother, Danzel Bezalel Tulung/male/son (8 months old baby) | N24: Augustine Elizabeth Pattipeilohy [모] Danzel Bezalel Tulung[아들, 0세] | O24: 3명/ (자녀 1명, 동반자 1명) | P24: =VALUE(LEFT(O24,1)) -> 3 | Q24: Agree | R24: 등록 | S24: bursary | T24: Rani Dwi Cahyaniputri | U24: 31644 | V24: rk.tulung@gmail.com | W24: 생년월일 일치, 이메일 일치, 이름 완전일치
A25: 46048.143 | B25: Jodi Wiles | D25: Female | E25: 29327 | F25: South Africa | G25: Christian Medical Fellowship South Africa | H25: National Executive Committee member | I25: =VLOOKUP(CLEAN(F25),'World Bank Categories'!$B$4:$C$220,2,FALSE) -> Middle income | J25: jodiwiles@gmail.com | K25: Main Congress Only | L25: July 1, July 2, July 3, July 4 | M25: 3: Michael Wiles, male, husband, michaelwiles@gmail.com; Amia Wiles, female, daughter (12 years old), jodiandmichaelwiles@gmail.com; Cayla Wiles, female, daughter (10 years old), jodiandmichaelwiles@gmail.com | N25: Michael Wiles [배우자(남편)] Amia Wiles [딸, 12세] Cayla Wiles [딸, 10세] | O25: 4명/ (자녀 2명, 배우자 1명) | P25: =VALUE(LEFT(O25,1)) -> 4 | Q25: Agree | R25: 등록 | S25: paid | T25: Jodi Wiles
A26: 46048.749 | B26: Phon Sophai | D26: Male | E26: 31397 | F26: Cambodia | G26: CCMF | H26: Medical doctor | I26: =VLOOKUP(CLEAN(F26),'World Bank Categories'!$B$4:$C$220,2,FALSE) -> Middle income | J26: uhs.sophai@gmail.com | K26: Main Congress Only | L26: July 1, July 2, July 3, July 4 | M26: 1, Dy Dalen, Female, Wife, 2, Phay Rattanak, Female, daughter. | N26: Dy Dalen [배우자(아내)] Phay Rattanak [딸, 7세] | O26: 3명/ (자녀 1명, 배우자 1명) | P26: =VALUE(LEFT(O26,1)) -> 3 | Q26: Agree | R26: 등록 | S26: bursary | T26: Phon Sophai | U26: 31397 | V26: uhs.sophai@gmail.com | W26: 생년월일 일치, 이메일 일치, 이름 완전일치
A27: 46052.179 | B27: Sybrand Johannes de Vaal | D27: Male | E27: 29271 | F27: South Africa | G27: CMF South Africa | H27: Dr | I27: =VLOOKUP(CLEAN(F27),'World Bank Categories'!$B$4:$C$220,2,FALSE) -> Middle income | J27: sjdevaal@gmail.com | K27: Pre-Conference + Main Congress | L27: June 30, July 1, July 2, July 3, July 4 | M27: 1, Celeste de Vaal, female, wife, celestedevaal@uct.ac.za 2, Nienke de Vaal, female, daughter, sjdevaal@gmail.com 3, Lira de Vaal, female, daughter, sjdevaal@gmail.com 4, Thandi de Vaal, daughter, sjdevaal@gmail.com 5, Ariana de Vaal, daughter, sjdevaal@gmail.com | N27: Celeste de Vaal [배우자(아내)] Nienke de Vaal [딸] Lira de Vaal [딸] Thandi de Vaal [딸] Ariana de Vaal [딸] | O27: 6명/ (자녀 5명, 배우자 1명) | P27: =VALUE(LEFT(O27,1)) -> 6 | Q27: Agree | R27: 등록 | S27: paid | T27: Sybrand Johannes de Vaal
A28: 46053.822 | B28: PHAM THI HUYEN | D28: Female | E28: 31669 | F28: Vietnam | G28: Hong phuc general hospital, Hai Phong, Vietnam | H28: Pharmacist | I28: =VLOOKUP(CLEAN(F28),'World Bank Categories'!$B$4:$C$220,2,FALSE) -> Middle income | J28: huyentrangshaloms@gmail.com | K28: Main Congress Only | L28: July 2, July 3, July 4 | M28: Nguyen Pham Viet An, son, huyentrangshaloms@gmail.com | N28: Nguyen Pham Viet An [아들] | O28: 2명/ (자녀 1명) | P28: =VALUE(LEFT(O28,1)) -> 2 | Q28: Agree | R28: 등록 | S28: bursary | T28: pham thi huyen | U28: 31669 | V28: huyentrangshaloms@gmail.com | W28: 생년월일 일치, 이메일 일치, 이름 완전일치
A29: 46090.384 | B29: Hamado | C29: Sawadogo | D29: Male | E29: 32873 | F29: Burkina Faso | G29: ICMDA | H29: Family Physician /RR | I29: =VLOOKUP(CLEAN(F29),'World Bank Categories'!$B$4:$C$220,2,FALSE) -> Low income | J29: hamadodavidsawadogo@gmail.com | K29: Pre-Conference + Main Congress | L29: June 29, June 30, July 1, July 2, July 3, July 4 | M29: May be my daughter Sawadogo Deogracias W. 5 year old Female | N29: Sawadogo Deogracias W [딸, 5세] | O29: 2명/ (자녀 1명) | P29: =VALUE(LEFT(O29,1)) -> 2 | Q29: Agree | R29: 등록 | S29: bursary | T29: HAMADO SAWADOGO | U29: 32873 | V29: hamadodavidsawadogo@gmail.com | W29: 생년월일 일치, 이메일 일치, 이름 유사도 100
A30: 46107.134 | B30: Jodi Isaacs Wiles | D30: Female | E30: 29327 | F30: South Africa | G30: UKZN/Queen Nandi Regional Hospital/CMF South Africa executive committee member | H30: Dr | I30: =VLOOKUP(CLEAN(F30),'World Bank Categories'!$B$4:$C$220,2,FALSE) -> Middle income | J30: jodiandmichaelwiles@gmail.com | K30: Main Congress Only | L30: July 2, July 3, July 4 | M30: 1, Michael Wiles, male, husband, jodiandmichaelwiles@gmail.com. 2. Amia Wiles, female, daughter, jodiandmichaelwiles@gmail.com, Cayla Wiles, female, daughter, jodiandmichaelwiles@gmail.com | N30: Amia Wiles (딸, 11세) Cayla Wiles (딸, 9세) | O30: 3명/ (자녀 2명) | P30: =VALUE(LEFT(O30,1)) -> 3 | Q30: Agree | R30: 등록 | S30: paid | T30: Jodi Wiles | U30: 29327 | V30: jodiwiles@gmail.com | W30: 생년월일 일치, 이름 일치
A31: 46122.73 | B31: KYUNGMIN JANG | C31: 장경민 | D31: Male | E31: 31381 | F31: Korea, Rep. | G31: His Hands On Africa (Rwanda) | H31: Dental Mission Director and Dental Surgeon | I31: =VLOOKUP(CLEAN(F31),'World Bank Categories'!$B$4:$C$220,2,FALSE) -> High income | J31: jang@hishandsonafrica.org | K31: Main Congress Only | L31: July 1, July 2, July 3, July 4 | M31: 3, MINHEE KIM(김민희), Female, Wife / CELINE JANG 장세린 (1 daughter, 7yrs) / Arin JANG 장아린 (2 daughter, 4 yrs) | N31: 김민희 (배우자) 장세린 (딸, 7세) 장하린(딸, 2세) | O31: 4명 / (자녀 2명, 배우자 1명) | P31: =VALUE(LEFT(O31,1)) -> 4 | Q31: Agree | R31: 등록 | S31: paid | T31: KYUNGMIN JANG | U31: 31117 | V31: jang@hishandsonafrica.org | W31: *갓샌즈 국가 Rwanda, 생년월일 불일치
A32: 46136.529 | B32: CHI MA | C32: N/A | D32: Female | E32: 31597 | F32: CHINA | G32: Peniel Church Muzha | H32: Doctor | I32: =VLOOKUP(CLEAN(F32),'World Bank Categories'!$B$4:$C$220,2,FALSE) -> Middle income | J32: mamachi07@gmail.com edgarwu@msn.com | K32: Pre-Conference + Main Congress | L32: June 29, June 30, July 1, July 2, July 3, July 4 | M32: PIN-HSIEN WU, male, husband, wu.edgar@gmail.com; EN-JIE WU, female, daughter, wu.edgar@gmail.com; EN-QI WU, male, son, wu.edgar@gmail.com | N32: PIN-HSIEN WU(배우자,남편) EN-JIE WU(딸) EN-QI WU(아들) | O32: 4명/ 자녀 2명, 배우자 1명 | P32: =VALUE(LEFT(O32,1)) -> 4 | Q32: Agree | R32: 등록 | S32: paid
A33: 46147.178 | B33: Helena Gomes | D33: Female | E33: 16387 | F33: Brazil | G33: CMF Brazil | H33: Mother accompanying applicant (Mireille Gomes) | I33: =VLOOKUP(CLEAN(F33),'World Bank Categories'!$B$4:$C$220,2,FALSE) -> Middle income | J33: gomesmibr@gmail.com | K33: Pre-Conference + Main Congress | L33: June 29, June 30, July 1, July 2, July 3, July 4 | M33: Mireille Gomes / Female / Daughter | N33: Mireille Gomes(딸) | O33: 2명(딸 1명) | P33: =VALUE(LEFT(O33,1)) -> 2 | Q33: Agree | R33: 등록 | S33: paid | T33: Helena Maria Freyesleben Silva de Miranda Gomes | U33: 16387 | V33: gomesmibr@gmail.com | W33: 이메일 일치; 이름 유사도 0.41; 생년월일 일치; Godsends row 1627; Payment Status=Paid; Amount=0 | X33: 720843
A34: 46163.633 | B34: MANOLITA JUNASA | D34: Female | E34: 21916 | F34: Philippines | G34: KAVOD Center for Special Persons | H34: Founder, Executive Director | I34: =VLOOKUP(CLEAN(F34),'World Bank Categories'!$B$4:$C$220,2,FALSE) -> Middle income | J34: mallette.p@gmail.com | K34: Main Congress Only | L34: June 29, June 30, July 1, July 2, July 3, July 4 | M34: 1, KYLE DAVID JUNASA, male, son, KyleDPJ518@gmail.com | N34: KYLE DAVID JUNASA(아들) | O34: 2명(아들 1명) | P34: =VALUE(LEFT(O34,1)) -> 2 | Q34: Agree | R34: 등록 | S34: paid | T34: MANOLITA JUNASA | U34: 21916 | V34: mallette.p@gmail.com | W34: 이메일 일치; 이름 유사도 1.00; 생년월일 일치; Godsends row 2459; Payment Status=Paid; Amount=1505 | X34: 725030
